Workbook

Sheet Data Performa
A2: CUSTOMER EXPERIENCE PERFORMANCE DATA
A3: 2025 - 2026
A4: IDM - TWC
A6: No | B6: Parameters | D6: Unit | E6: Target | F6: 2025 | S6: 2026
F7: JAN | G7: FEB | H7: MAR | I7: APR | J7: MAY | K7: JUN | L7: JUL | M7: AUG | N7: SEP | O7: OCT | P7: NOV | Q7: DEC | R7: TOTAL | S7: JAN | T7: FEB | U7: MAR | V7: APR | W7: MAY | X7: JUNE
A8: 1 | B8: Customer Satisfaction (Survey Sensum)
B9: a. | C9: CSAT - Overall | D9: Scale 1-5 | N9: 4.23 | O9: 4.57 | P9: 4.66 | Q9: 4.59 | R9: =AVERAGE(N9:Q9) -> 4.5125 | S9: =AVERAGE('IDM - TWC Borobudur'!S9,'IDM - TWC Prambanan'!S9) -> 4.71 | T9: =AVERAGE('IDM - TWC Borobudur'!T9,'IDM - TWC Prambanan'!T9) -> 4.71 | U9: =AVERAGE('IDM - TWC Borobudur'!U9,'IDM - TWC Prambanan'!U9) -> 3.175 | V9: =AVERAGE('IDM - TWC Borobudur'!V9,'IDM - TWC Prambanan'!V9) -> 3.84 | W9: =AVERAGE('IDM - TWC Borobudur'!W9,'IDM - TWC Prambanan'!W9) -> 4.18 | X9: =AVERAGE('IDM - TWC Borobudur'!X9,'IDM - TWC Prambanan'!X9) -> 4.37
B10: b. | C10: CSAT - People | D10: Scale 1-5 | N10: 4.51 | O10: 4.69 | P10: 4.75 | Q10: 4.69 | R10: =AVERAGE(N10:Q10) -> 4.66 | S10: =AVERAGE('IDM - TWC Borobudur'!S10,'IDM - TWC Prambanan'!S10) -> 4.81 | T10: =AVERAGE('IDM - TWC Borobudur'!T10,'IDM - TWC Prambanan'!T10) -> 4.77 | U10: =AVERAGE('IDM - TWC Borobudur'!U10,'IDM - TWC Prambanan'!U10) -> 3.65 | V10: =AVERAGE('IDM - TWC Borobudur'!V10,'IDM - TWC Prambanan'!V10) -> 4.025 | W10: =AVERAGE('IDM - TWC Borobudur'!W10,'IDM - TWC Prambanan'!W10) -> 4.25 | X10: =AVERAGE('IDM - TWC Borobudur'!X10,'IDM - TWC Prambanan'!X10) -> 4.48
B11: c. | C11: CSAT - Process | D11: Scale 1-5 | N11: 4.17 | O11: 4.59 | P11: 4.68 | Q11: 4.6 | R11: =AVERAGE(N11:Q11) -> 4.51 | S11: =AVERAGE('IDM - TWC Borobudur'!S11,'IDM - TWC Prambanan'!S11) -> 4.73 | T11: =AVERAGE('IDM - TWC Borobudur'!T11,'IDM - TWC Prambanan'!T11) -> 4.7 | U11: =AVERAGE('IDM - TWC Borobudur'!U11,'IDM - TWC Prambanan'!U11) -> 3.525 | V11: =AVERAGE('IDM - TWC Borobudur'!V11,'IDM - TWC Prambanan'!V11) -> 3.55 | W11: =AVERAGE('IDM - TWC Borobudur'!W11,'IDM - TWC Prambanan'!W11) -> 4.25 | X11: =AVERAGE('IDM - TWC Borobudur'!X11,'IDM - TWC Prambanan'!X11) -> 4.35
B12: d. | C12: CSAT - Premises | D12: Scale 1-5 | N12: 4.46 | O12: 4.7 | P12: 4.73 | Q12: 4.58 | R12: =AVERAGE(N12:Q12) -> 4.6175 | S12: =AVERAGE('IDM - TWC Borobudur'!S12,'IDM - TWC Prambanan'!S12) -> 4.72 | T12: =AVERAGE('IDM - TWC Borobudur'!T12,'IDM - TWC Prambanan'!T12) -> 4.65 | U12: =AVERAGE('IDM - TWC Borobudur'!U12,'IDM - TWC Prambanan'!U12) -> 3.7 | V12: =AVERAGE('IDM - TWC Borobudur'!V12,'IDM - TWC Prambanan'!V12) -> 3.66 | W12: =AVERAGE('IDM - TWC Borobudur'!W12,'IDM - TWC Prambanan'!W12) -> 3.9 | X12: =AVERAGE('IDM - TWC Borobudur'!X12,'IDM - TWC Prambanan'!X12) -> 4.2
A13: 2 | B13: Call Center Performance
B14: a. | C14: Volume of Call | D14: Numbers | F14: ='IDM - TWC Borobudur'!F14+'IDM - TWC Prambanan'!F14 -> 38 | G14: ='IDM - TWC Borobudur'!G14+'IDM - TWC Prambanan'!G14 -> 28 | H14: ='IDM - TWC Borobudur'!H14+'IDM - TWC Prambanan'!H14 -> 10 | I14: ='IDM - TWC Borobudur'!I14+'IDM - TWC Prambanan'!I14 -> 71 | J14: ='IDM - TWC Borobudur'!J14+'IDM - TWC Prambanan'!J14 -> 60 | K14: ='IDM - TWC Borobudur'!K14+'IDM - TWC Prambanan'!K14 -> 93 | L14: ='IDM - TWC Borobudur'!L14+'IDM - TWC Prambanan'!L14 -> 3 | M14: ='IDM - TWC Borobudur'!M14+'IDM - TWC Prambanan'!M14 -> 43 | ... Q14: ='IDM - TWC Borobudur'!Q14+'IDM - TWC Prambanan'!Q14 -> 51 | R14: =SUM(F14:Q14) -> 540 | S14: ='IDM - TWC Borobudur'!S14+'IDM - TWC Prambanan'!S14 -> 127 | T14: ='IDM - TWC Borobudur'!T14+'IDM - TWC Prambanan'!T14 -> 95 | U14: ='IDM - TWC Borobudur'!U14+'IDM - TWC Prambanan'!U14 -> 121 | V14: ='IDM - TWC Borobudur'!V14+'IDM - TWC Prambanan'!V14 -> 91 | W14: ='IDM - TWC Borobudur'!W14+'IDM - TWC Prambanan'!W14 -> 101 | X14: ='IDM - TWC Borobudur'!X14+'IDM - TWC Prambanan'!X14 -> 84
B15: b. | C15: First Call Resolution | D15: Percentage (%) | Y15: call abandon/all
B16: c. | C16: Service Level | D16: Percentage (%)
A17: 3 | B17: Social Media Monitoring
B18: a. | C18: Volume of Interaction | D18: Numbers | F18: 75300 | G18: 25100 | H18: 64700 | I18: 319500 | J18: 94300 | K18: 31500 | L18: 20100 | M18: 5200 | N18: 18400 | O18: 17700 | P18: 18200 | Q18: 75300 | R18: =SUM(F18:Q18) -> 765300 | S18: 12500 | T18: 19900 | U18: 22200 | V18: 20400 | W18: 183400 | X18: 122100 | Y18: source langit biru volume interaction all account
B19: b. | C19: Net Sentiment Score | D19: Percentage (%) | F19: 0.0932 | G19: 0.1995 | H19: 0.0892 | I19: 0.093 | J19: 0.0902 | K19: 0.0082 | L19: 0.0417 | M19: 0.0721 | N19: 0.1852 | O19: 0.069 | P19: 0.1134 | Q19: 0.0494 | R19: =SUM(F19:Q19) -> 1.1041 | S19: 0.1257 | T19: 0.1271 | U19: 0.1115 | V19: 0.0809 | W19: 0.0851 | X19: 0.1841 | Y19: manual raw data dari langit biru
B20: c. | C20: Average Response Time | D20: Hours
B21: d. | C21: Respons to Sentiment Ratio | D21: 0,00 - 1,00 | F21: 0.26 | G21: 0.06 | H21: 0.43 | I21: 0.1 | J21: 0.11 | K21: 0.25 | L21: 0.11 | M21: 0.46 | N21: 0.1 | O21: 0.21 | P21: 0.24 | Q21: 0.16 | R21: =SUM(F21:Q21) -> 2.49 | S21: 0.12 | T21: 0.06 | U21: 0.08 | V21: 0.11 | W21: 0.09 | X21: 0.05
A22: 4 | B22: Complaint Handling
B23: a. | C23: Total Complaint | D23: Numbers | E23: Cust review | F23: =SUM('IDM - TWC Borobudur'!F23,'IDM - TWC Prambanan'!F23) -> 86 | G23: =SUM('IDM - TWC Borobudur'!G23,'IDM - TWC Prambanan'!G23) -> 49 | H23: =SUM('IDM - TWC Borobudur'!H23,'IDM - TWC Prambanan'!H23) -> 31 | I23: =SUM('IDM - TWC Borobudur'!I23,'IDM - TWC Prambanan'!I23) -> 119 | J23: =SUM('IDM - TWC Borobudur'!J23,'IDM - TWC Prambanan'!J23) -> 66 | K23: =SUM('IDM - TWC Borobudur'!K23,'IDM - TWC Prambanan'!K23) -> 43 | L23: =SUM('IDM - TWC Borobudur'!L23,'IDM - TWC Prambanan'!L23) -> 101 | M23: =SUM('IDM - TWC Borobudur'!M23,'IDM - TWC Prambanan'!M23) -> 50 | ... Q23: =SUM('IDM - TWC Borobudur'!Q23,'IDM - TWC Prambanan'!Q23) -> 40 | R23: =SUM(F23:Q23) -> 673 | S23: =SUM('IDM - TWC Borobudur'!S23,'IDM - TWC Prambanan'!S23) -> 27 | T23: =SUM('IDM - TWC Borobudur'!T23,'IDM - TWC Prambanan'!T23) -> 29 | U23: =SUM('IDM - TWC Borobudur'!U23,'IDM - TWC Prambanan'!U23) -> 44 | V23: =SUM('IDM - TWC Borobudur'!V23,'IDM - TWC Prambanan'!V23) -> 26 | W23: =SUM('IDM - TWC Borobudur'!W23,'IDM - TWC Prambanan'!W23) -> 35 | X23: =SUM('IDM - TWC Borobudur'!X23,'IDM - TWC Prambanan'!X23) -> 28
E24: CC | F24: =SUM('IDM - TWC Borobudur'!F24,'IDM - TWC Prambanan'!F24) -> 10 | G24: =SUM('IDM - TWC Borobudur'!G24,'IDM - TWC Prambanan'!G24) -> 6 | H24: =SUM('IDM - TWC Borobudur'!H24,'IDM - TWC Prambanan'!H24) -> 2 | I24: =SUM('IDM - TWC Borobudur'!I24,'IDM - TWC Prambanan'!I24) -> 8 | J24: =SUM('IDM - TWC Borobudur'!J24,'IDM - TWC Prambanan'!J24) -> 3 | K24: =SUM('IDM - TWC Borobudur'!K24,'IDM - TWC Prambanan'!K24) -> 3 | L24: =SUM('IDM - TWC Borobudur'!L24,'IDM - TWC Prambanan'!L24) -> 5 | M24: =SUM('IDM - TWC Borobudur'!M24,'IDM - TWC Prambanan'!M24) -> 6 | ... Q24: =SUM('IDM - TWC Borobudur'!Q24,'IDM - TWC Prambanan'!Q24) -> 0 | R24: =SUM(F24:Q24) -> 47 | S24: =SUM('IDM - TWC Borobudur'!S24,'IDM - TWC Prambanan'!S24) -> 7 | T24: =SUM('IDM - TWC Borobudur'!T24,'IDM - TWC Prambanan'!T24) -> 2 | U24: =SUM('IDM - TWC Borobudur'!U24,'IDM - TWC Prambanan'!U24) -> 0 | V24: =SUM('IDM - TWC Borobudur'!V24,'IDM - TWC Prambanan'!V24) -> 3 | W24: =SUM('IDM - TWC Borobudur'!W24,'IDM - TWC Prambanan'!W24) -> 4 | X24: =SUM('IDM - TWC Borobudur'!X24,'IDM - TWC Prambanan'!X24) -> 13
E25: Langit biru | F25: =SUM('IDM - TWC Borobudur'!F25,'IDM - TWC Prambanan'!F25) -> 7 | G25: =SUM('IDM - TWC Borobudur'!G25,'IDM - TWC Prambanan'!G25) -> 1 | H25: =SUM('IDM - TWC Borobudur'!H25,'IDM - TWC Prambanan'!H25) -> 0 | I25: =SUM('IDM - TWC Borobudur'!I25,'IDM - TWC Prambanan'!I25) -> 8 | J25: =SUM('IDM - TWC Borobudur'!J25,'IDM - TWC Prambanan'!J25) -> 52 | K25: =SUM('IDM - TWC Borobudur'!K25,'IDM - TWC Prambanan'!K25) -> 34 | L25: =SUM('IDM - TWC Borobudur'!L25,'IDM - TWC Prambanan'!L25) -> 8 | M25: =SUM('IDM - TWC Borobudur'!M25,'IDM - TWC Prambanan'!M25) -> 2 | ... Q25: =SUM('IDM - TWC Borobudur'!Q25,'IDM - TWC Prambanan'!Q25) -> 11 | R25: =SUM(F25:Q25) -> 130 | S25: =SUM('IDM - TWC Borobudur'!S25,'IDM - TWC Prambanan'!S25) -> 78 | T25: =SUM('IDM - TWC Borobudur'!T25,'IDM - TWC Prambanan'!T25) -> 3 | U25: =SUM('IDM - TWC Borobudur'!U25,'IDM - TWC Prambanan'!U25) -> 13 | V25: =SUM('IDM - TWC Borobudur'!V25,'IDM - TWC Prambanan'!V25) -> 0 | W25: =SUM('IDM - TWC Borobudur'!W25,'IDM - TWC Prambanan'!W25) -> 5 | X25: =SUM('IDM - TWC Borobudur'!X25,'IDM - TWC Prambanan'!X25) -> 2
E26: On site (data from unit) | F26: =SUM('IDM - TWC Borobudur'!F26,'IDM - TWC Prambanan'!F26) -> 4 | G26: =SUM('IDM - TWC Borobudur'!G26,'IDM - TWC Prambanan'!G26) -> 2 | H26: =SUM('IDM - TWC Borobudur'!H26,'IDM - TWC Prambanan'!H26) -> 0 | I26: =SUM('IDM - TWC Borobudur'!I26,'IDM - TWC Prambanan'!I26) -> 0 | J26: =SUM('IDM - TWC Borobudur'!J26,'IDM - TWC Prambanan'!J26) -> 2 | K26: =SUM('IDM - TWC Borobudur'!K26,'IDM - TWC Prambanan'!K26) -> 0 | L26: =SUM('IDM - TWC Borobudur'!L26,'IDM - TWC Prambanan'!L26) -> 0 | M26: =SUM('IDM - TWC Borobudur'!M26,'IDM - TWC Prambanan'!M26) -> 1 | ... X26: =SUM('IDM - TWC Borobudur'!X26,'IDM - TWC Prambanan'!X26) -> 0
E27: TOTAL | F27: =SUM(F23:F26) -> 107 | G27: =SUM(G23:G26) -> 58 | H27: =SUM(H23:H26) -> 33 | I27: =SUM(I23:I26) -> 135 | J27: =SUM(J23:J26) -> 123 | K27: =SUM(K23:K26) -> 80 | L27: =SUM(L23:L26) -> 114 | M27: =SUM(M23:M26) -> 59 | ... X27: =SUM(X23:X26) -> 43
B28: b. | C28: Completed | D28: Numbers | F28: =F27 -> 107
B29: c. | C29: Progress | D29: Numbers
B30: d. | C30: Untouch | D30: Numbers
B31: e. | C31: Complaint Resolution Rate | D31: Percentage (%) | F31: =F28/F27 -> 1
B32: f. | C32: Average Time Resolution | D32: Day

Sheet IDM - TWC Borobudur
A2: CUSTOMER EXPERIENCE PERFORMANCE DATA
A3: 2025 - 2026
A4: IDM - TWC Borobudur
A6: No | B6: Parameters | D6: Unit | E6: Target | F6: 2025 | S6: 2026
F7: JAN | G7: FEB | H7: MAR | I7: APR | J7: MAY | K7: JUN | L7: JUL | M7: AUG | N7: SEP | O7: OCT | P7: NOV | Q7: DEC | R7: TOTAL | S7: JAN | T7: FEB | U7: MAR | V7: APR | W7: MAY | X7: JUN
A8: 1 | B8: Customer Satisfaction (Survey Sensum)
B9: a. | C9: CSAT - Overall | D9: Scale 1-5 | F9: 0 | G9: 0 | H9: 0 | I9: 0 | J9: 0 | K9: 0 | L9: 0 | M9: 0 | N9: 4.6 | O9: 4.61 | P9: 4.64 | Q9: 4.15 | R9: =AVERAGE(N9:Q9) -> 4.5 | S9: - | T9: - | U9: 3.25 | V9: 4.68 | W9: 4.66 | X9: 4.64
B10: b. | C10: CSAT - People | D10: Scale 1-5 | F10: 0 | G10: 0 | H10: 0 | I10: 0 | J10: 0 | K10: 0 | L10: 0 | M10: 0 | N10: 4.59 | O10: 4.74 | P10: 4.78 | Q10: 4.3 | R10: =AVERAGE(N10:Q10) -> 4.6025 | S10: - | T10: - | U10: 4 | V10: 4.75 | W10: 5 | X10: 4.56
B11: c. | C11: CSAT - Process | D11: Scale 1-5 | F11: 0 | G11: 0 | H11: 0 | I11: 0 | J11: 0 | K11: 0 | L11: 0 | M11: 0 | N11: 4.6 | O11: 4.7 | P11: 4.72 | Q11: 4.1 | R11: =AVERAGE(N11:Q11) -> 4.53 | S11: - | T11: - | U11: 3.75 | V11: 4.2 | W11: 4.3 | X11: 4.7
B12: d. | C12: CSAT - Premises | D12: Scale 1-5 | F12: 0 | G12: 0 | H12: 0 | I12: 0 | J12: 0 | K12: 0 | L12: 0 | M12: 0 | N12: 4.7 | O12: 4.76 | P12: 4.75 | Q12: 4.35 | R12: =AVERAGE(N12:Q12) -> 4.64 | S12: - | T12: - | U12: 4 | V12: 4.32 | W12: 4.2 | X12: 4.5
A13: 2 | B13: Call Center Performance
B14: a. | C14: Volume of Call | D14: Numbers | F14: 28 | G14: 23 | H14: 6 | I14: 51 | J14: 41 | K14: 60 | L14: 1 | M14: 28 | N14: 6 | O14: 33 | P14: 49 | Q14: 27 | R14: =SUM(F14:Q14) -> 353 | S14: 80 | T14: 66 | U14: 75 | V14: 54 | W14: 48 | X14: 53
B15: b. | C15: First Call Resolution | D15: Percentage (%)
B16: c. | C16: Service Level | D16: Percentage (%)
A17: 3 | B17: Social Media Monitoring
B18: a. | C18: Volume of Interaction | D18: Numbers | F18: 75300 | G18: 25100 | H18: 64700 | I18: 319500 | J18: 94300 | K18: 31500 | L18: 20100 | M18: 5200 | N18: 18400 | O18: 17700 | P18: 18200 | Q18: 75300 | R18: =SUM(F18:Q18) -> 765300 | S18: 12500 | T18: 19900 | U18: 22200 | V18: 20400 | W18: 183400 | X18: 122100
B19: b. | C19: Net Sentiment Score | D19: Percentage (%) | F19: 0.1202 | G19: 0.0476 | H19: 0.0467 | I19: 0.0305 | J19: 0.1192 | K19: -0.065 | L19: 0.0521 | M19: 0.127 | N19: 0.2789 | O19: 0.1276 | P19: 0.1458 | Q19: 0.0872 | R19: =SUM(F19:Q19) -> 1.1178 | S19: -0.037 | T19: 0.3158 | U19: 0.2459 | V19: 0.0809 | W19: 0.0851 | X19: 0.1841
B20: c. | C20: Average Response Time | D20: Hours
B21: d. | C21: Respons to Sentiment Ratio | D21: 0,00 - 1,00 | F21: 0.26 | G21: 0.06 | H21: 0.43 | I21: 0.1 | J21: 0.11 | K21: 0.25 | L21: 0.11 | M21: 0.46 | N21: 0.1 | O21: 0.21 | P21: 0.24 | Q21: 0.16 | R21: =SUM(F21:Q21) -> 2.49 | S21: 0.12 | T21: 0.06 | U21: 0.08 | V21: 0.11 | W21: 0.09 | X21: 0.05
A22: 4 | B22: Complaint Handling
B23: a. | C23: Total Complaint | D23: Numbers | E23: Cust review Borobudur | F23: 67 | G23: 35 | H23: 25 | I23: 93 | J23: 50 | K23: 31 | L23: 73 | M23: 29 | N23: 23 | O23: 19 | P23: 14 | Q23: 30 | R23: =SUM(F23:Q23) -> 489 | S23: 14 | T23: 13 | U23: 23 | V23: 16 | W23: 22 | X23: 12
E24: CC | F24: 8 | G24: 3 | H24: 2 | I24: 6 | J24: 2 | K24: 2 | L24: 1 | M24: 6 | N24: 0 | O24: 4 | P24: 0 | Q24: 0 | R24: =SUM(F24:Q24) -> 34 | S24: 5 | T24: 2 | U24: 0 | V24: 2 | W24: 3 | X24: 11
E25: Langit biru | F25: 5 | G25: 1 | H25: 0 | I25: 4 | J25: 52 | K25: 24 | L25: 0 | M25: 1 | N25: 3 | O25: 0 | P25: 3 | Q25: 6 | R25: =SUM(F25:Q25) -> 99 | S25: 77 | T25: 2 | U25: 13 | V25: 0 | W25: 4 | X25: 2
E26: On site (data from unit) | F26: 4 | G26: 2 | H26: 0 | I26: 0 | J26: 2 | K26: 0 | L26: 0 | M26: 1 | N26: 0 | O26: 0 | P26: 3 | Q26: 0 | R26: =SUM(F26:Q26) -> 12 | S26: 4 | T26: 1 | U26: 1 | V26: 1 | W26: 0 | X26: 0
B27: b. | C27: Completed | D27: Numbers
B28: c. | C28: Progress | D28: Numbers
B29: d. | C29: Untouch | D29: Numbers
B30: e. | C30: Complaint Resolution Rate | D30: Percentage (%)
B31: f. | C31: Average Time Resolution | D31: Day

Sheet IDM - TWC Prambanan
A2: CUSTOMER EXPERIENCE PERFORMANCE DATA
A3: 2025 - 2026
A4: IDM - TWC Prambanan
A6: No | B6: Parameters | D6: Unit | E6: Target | F6: 2025 | S6: 2026
F7: JAN | G7: FEB | H7: MAR | I7: APR | J7: MAY | K7: JUN | L7: JUL | M7: AUG | N7: SEP | O7: OCT | P7: NOV | Q7: DEC | R7: TOTAL | S7: JAN | T7: FEB | U7: MAR | V7: APR | W7: MAY | X7: JUN
A8: 1 | B8: Customer Satisfaction (Survey Sensum)
B9: a. | C9: CSAT - Overall | D9: Scale 1-5 | F9: 0 | G9: 0 | H9: 0 | I9: 0 | J9: 0 | K9: 0 | L9: 0 | M9: 0 | N9: 3.97 | O9: 3.88 | P9: 3.88 | Q9: 2.75 | R9: =AVERAGE(N9:Q9) -> 3.62 | S9: 4.71 | T9: 4.71 | U9: 3.1 | V9: 3 | W9: 3.7 | X9: 4.1
B10: b. | C10: CSAT - People | D10: Scale 1-5 | F10: 0 | G10: 0 | H10: 0 | I10: 0 | J10: 0 | K10: 0 | L10: 0 | M10: 0 | N10: 4.71 | O10: 4.18 | P10: 4 | Q10: 3.33 | R10: =AVERAGE(N10:Q10) -> 4.055 | S10: 4.81 | T10: 4.77 | U10: 3.3 | V10: 3.3 | W10: 3.5 | X10: 4.4
B11: c. | C11: CSAT - Process | D11: Scale 1-5 | F11: 0 | G11: 0 | H11: 0 | I11: 0 | J11: 0 | K11: 0 | L11: 0 | M11: 0 | N11: 3.96 | O11: 3.92 | P11: 3.63 | Q11: 3.83 | R11: =AVERAGE(N11:Q11) -> 3.835 | S11: 4.73 | T11: 4.7 | U11: 3.3 | V11: 2.9 | W11: 4.2 | X11: 4
B12: d. | C12: CSAT - Premises | D12: Scale 1-5 | F12: 0 | G12: 0 | H12: 0 | I12: 0 | J12: 0 | K12: 0 | L12: 0 | M12: 0 | N12: 4.03 | O12: 4.08 | P12: 3.75 | Q12: 2.83 | R12: =AVERAGE(N12:Q12) -> 3.6725 | S12: 4.72 | T12: 4.65 | U12: 3.4 | V12: 3 | W12: 3.6 | X12: 3.9
A13: 2 | B13: Call Center Performance
B14: a. | C14: Volume of Call | D14: Numbers | F14: 10 | G14: 5 | H14: 4 | I14: 20 | J14: 19 | K14: 33 | L14: 2 | M14: 15 | N14: 1 | O14: 26 | P14: 28 | Q14: 24 | R14: =SUM(F14:Q14) -> 187 | S14: 47 | T14: 29 | U14: 46 | V14: 37 | W14: 53 | X14: 31
B15: b. | C15: First Call Resolution | D15: Percentage (%)
B16: c. | C16: Service Level | D16: Percentage (%)
A17: 3 | B17: Social Media Monitoring
B18: a. | C18: Volume of Interaction | D18: Numbers | F18: 75300 | G18: 25100 | H18: 64700 | I18: 319500 | J18: 94300 | K18: 31500 | L18: 20100 | M18: 5200 | N18: 18400 | O18: 17700 | P18: 18200 | Q18: 75300 | R18: =SUM(F18:Q18) -> 765300 | S18: 12500 | T18: 19900 | U18: 22200 | V18: 20400 | W18: 183400 | X18: 122100 | Z18: source langit biru volume interaction all account
B19: b. | C19: Net Sentiment Score | D19: Percentage (%) | F19: 0.0825 | G19: 0.3252 | H19: 0.1647 | I19: 0.2733 | J19: 0.0707 | K19: 0.0202 | L19: 0.0674 | M19: 0.0701 | N19: 0.101 | O19: 0.0236 | P19: 0.0703 | Q19: 0.0461 | R19: =SUM(F19:Q19) -> 1.3151 | S19: 0.1257 | T19: 0.1271 | U19: 0.1115 | V19: 0.0809 | W19: 0.0851 | X19: 0.1841 | Z19: manual raw data dari langit biru
B20: c. | C20: Average Response Time | D20: Hours
B21: d. | C21: Respons to Sentiment Ratio | D21: 0,00 - 1,00 | F21: 0.26 | G21: 0.06 | H21: 0.43 | I21: 0.1 | J21: 0.11 | K21: 0.25 | L21: 0.11 | M21: 0.46 | N21: 0.1 | O21: 0.21 | P21: 0.24 | Q21: 0.16 | R21: =SUM(F21:Q21) -> 2.49 | S21: 0.12 | T21: 0.06 | U21: 0.08 | V21: 0.11 | W21: 0.09 | X21: 0.05
A22: 4 | B22: Complaint Handling
B23: a. | C23: Total Complaint | D23: Numbers | E23: Cust review Prambanan | F23: 19 | G23: 14 | H23: 6 | I23: 26 | J23: 16 | K23: 12 | L23: 28 | M23: 21 | N23: 10 | O23: 14 | P23: 8 | Q23: 10 | R23: =SUM(F23:Q23) -> 184 | S23: 13 | T23: 16 | U23: 21 | V23: 10 | W23: 13 | X23: 16
E24: CC | F24: 2 | G24: 3 | H24: 0 | I24: 2 | J24: 1 | K24: 1 | L24: 4 | M24: 0 | N24: 0 | O24: 0 | P24: 0 | Q24: 0 | R24: =SUM(F24:Q24) -> 13 | S24: 2 | T24: 0 | U24: 0 | V24: 1 | W24: 1 | X24: 2
E25: Langit biru | F25: 2 | G25: 0 | H25: 0 | I25: 4 | J25: 0 | K25: 10 | L25: 8 | M25: 1 | N25: 0 | O25: 1 | P25: 0 | Q25: 5 | R25: =SUM(F25:Q25) -> 31 | S25: 1 | T25: 1 | U25: 0 | V25: 0 | W25: 1 | X25: 0
E26: On site (data from unit) | F26: 0 | G26: 0 | H26: 0 | I26: 0 | J26: 0 | K26: 0 | L26: 0 | M26: 0 | N26: 0 | O26: 0 | P26: 0 | Q26: 0 | R26: =SUM(F26:Q26) -> 0 | S26: 2 | T26: 0 | U26: 0 | V26: 0 | W26: 0 | X26: 0
B27: b. | C27: Completed | D27: Numbers
B28: c. | C28: Progress | D28: Numbers
B29: d. | C29: Untouch | D29: Numbers
B30: e. | C30: Complaint Resolution Rate | D30: Percentage (%)
B31: f. | C31: Average Time Resolution | D31: Day

Sheet Data Statistik-TWC
A1: No | B1: Item Data | E1: Keterangan Pengisian | F1: 45658 | G1: 45689 | H1: 45717 | I1: 45748 | J1: 45778 | K1: 45809 | L1: 45839 | M1: 45870 | N1: 45901 | O1: 45931 | P1: 45962 | Q1: 45992 | R1: 46023 | S1: 46054 | T1: 46082 | U1: 46113 | V1: 46143 | W1: 46174
A2: 1 | B2: Jumlah Pengunjung | E2: Data Total Pengunjung (Per Cabang / Line of Business) | F2: =SUM(F3:F6) -> 453639 | G2: =SUM(G3:G6) -> 281302 | H2: =SUM(H3:H6) -> 68929 | I2: =SUM(I3:I6) -> 387606 | J2: =SUM(J3:J6) -> 336253 | K2: =SUM(K3:K6) -> 369979 | L2: =SUM(L3:L6) -> 412770 | M2: =SUM(M3:M6) -> 250523 | ... W2: =SUM(W3:W6) -> 413329
C3: Borobudur | F3: 128957 | G3: 67427 | H3: 31120 | I3: 129432 | J3: 92067 | K3: 124937 | L3: 141627 | M3: 91970 | N3: 74228 | O3: 71159 | P3: 76409 | Q3: 138113 | R3: 86434 | S3: 50961 | T3: 89033 | U3: 59039 | V3: 95451 | W3: 116195
C4: Prambanan | F4: 302035 | G4: 196094 | H4: 33288 | I4: 236462 | J4: 215811 | K4: 222054 | L4: 244796 | M4: 138163 | N4: 137227 | O4: 150496 | P4: 150782 | Q4: 308084 | R4: 214389 | S4: 105895 | T4: 159109 | U4: 176451 | V4: 261511 | W4: 270901
C5: Ratu Boko | F5: 14131 | G5: 6405 | H5: 3138 | I5: 12128 | J5: 11770 | K5: 13064 | L5: 12591 | M5: 8432 | N5: 8299 | O5: 7008 | P5: 7144 | Q5: 13752 | R5: 8470 | S5: 5019 | T5: 8003 | U5: 5867 | V5: 9933 | W5: 10349
C6: Teater Pentas | F6: 8516 | G6: 11376 | H6: 1383 | I6: 9584 | J6: 16605 | K6: 9924 | L6: 13756 | M6: 11958 | N6: 10089 | O6: 12716 | P6: 9672 | Q6: 14459 | R6: 12991 | S6: 7034 | T6: 6298 | U6: 14793 | V6: 17014 | W6: 15884
A7: 2 | B7: Total Interaksi | E7: Total Interaksi (Per Cabang / Line of Business) dari Voice of Customer (pengaduan, permintaan, pertanyaan, informasi dan apresiasi). | F7: =SUM(F9:F15) -> 1523 | G7: =SUM(G9:G15) -> 930 | H7: =SUM(H9:H15) -> 512 | I7: =SUM(I9:I15) -> 1759 | J7: =SUM(J9:J15) -> 1663 | K7: =SUM(K9:K15) -> 1222 | L7: =SUM(L9:L15) -> 1438 | M7: =SUM(M9:M15) -> 112 | ... W7: =SUM(W9:W15) -> #VALUE!
A8: 3 | B8: Jumlah interaksi per-kategory
B9: a | C9: Pengaduan/Keluhan | E9: Bersumber dari Telepon, Customer Service/tatap muka, Email, Kotak Saran, Live Chat, Whatsapp, Instagram dan Twitter | F9: =F17+F24+F31+F38+F45+F52+F59+F66+F73+F80 -> 15 | G9: =G17+G24+G31+G38+G45+G52+G59+G66+G73+G80 -> 8 | H9: =H17+H24+H31+H38+H45+H52+H59+H66+H73+H80 -> 4 | I9: =I17+I24+I31+I38+I45+I52+I59+I66+I73+I80 -> 16 | J9: =J17+J24+J31+J38+J45+J52+J59+J66+J73+J80 -> 10 | K9: =K17+K24+K31+K38+K45+K52+K59+K66+K73+K80 -> 14 | L9: =L17+L24+L31+L38+L45+L52+L59+L66+L73+L80 -> 25 | M9: =M17+M24+M31+M38+M45+M52+M59+M66+M73+M80 -> 25 | ... W9: =W17+W24+W31+W38+W45+W52+W59+W66+W73+W80 -> #VALUE!
B10: b | C10: Permintaan/Reservasi/Product Inquiry | F10: =F18+F25+F32+F39+F46+F53+F60+F67+F74+F81 -> 9 | G10: =G18+G25+G32+G39+G46+G53+G60+G67+G74+G81 -> 0 | H10: =H18+H25+H32+H39+H46+H53+H60+H67+H74+H81 -> 0 | I10: =I18+I25+I32+I39+I46+I53+I60+I67+I74+I81 -> 0 | J10: =J18+J25+J32+J39+J46+J53+J60+J67+J74+J81 -> 0 | K10: =K18+K25+K32+K39+K46+K53+K60+K67+K74+K81 -> 0 | L10: =L18+L25+L32+L39+L46+L53+L60+L67+L74+L81 -> 0 | M10: =M18+M25+M32+M39+M46+M53+M60+M67+M74+M81 -> 19 | ... W10: =W18+W25+W32+W39+W46+W53+W60+W67+W74+W81 -> #VALUE!
B11: c | C11: Pertanyaan | F11: =F19+F26+F33+F40+F47+F54+F61+F68+F75+F82 -> 0 | G11: =G19+G26+G33+G40+G47+G54+G61+G68+G75+G82 -> 0 | H11: =H19+H26+H33+H40+H47+H54+H61+H68+H75+H82 -> 0 | I11: =I19+I26+I33+I40+I47+I54+I61+I68+I75+I82 -> 0 | J11: =J19+J26+J33+J40+J47+J54+J61+J68+J75+J82 -> 0 | K11: =K19+K26+K33+K40+K47+K54+K61+K68+K75+K82 -> 0 | L11: =L19+L26+L33+L40+L47+L54+L61+L68+L75+L82 -> 0 | M11: =M19+M26+M33+M40+M47+M54+M61+M68+M75+M82 -> 0 | ... W11: =W19+W26+W33+W40+W47+W54+W61+W68+W75+W82 -> #VALUE!
B12: d | C12: Informasi | F12: =F20+F27+F34+F41+F48+F55+F62+F69+F76+F83 -> 1499 | G12: =G20+G27+G34+G41+G48+G55+G62+G69+G76+G83 -> 922 | H12: =H20+H27+H34+H41+H48+H55+H62+H69+H76+H83 -> 508 | I12: =I20+I27+I34+I41+I48+I55+I62+I69+I76+I83 -> 1743 | J12: =J20+J27+J34+J41+J48+J55+J62+J69+J76+J83 -> 1653 | K12: =K20+K27+K34+K41+K48+K55+K62+K69+K76+K83 -> 1208 | L12: =L20+L27+L34+L41+L48+L55+L62+L69+L76+L83 -> 1413 | M12: =M20+M27+M34+M41+M48+M55+M62+M69+M76+M83 -> 68 | ... W12: =W20+W27+W34+W41+W48+W55+W62+W69+W76+W83 -> #VALUE!
B13: e | C13: Apresiasi | F13: =F21+F28+F35+F42+F49+F56+F63+F70+F77+F84 -> 0 | G13: =G21+G28+G35+G42+G49+G56+G63+G70+G77+G84 -> 0 | H13: =H21+H28+H35+H42+H49+H56+H63+H70+H77+H84 -> 0 | I13: =I21+I28+I35+I42+I49+I56+I63+I70+I77+I84 -> 0 | J13: =J21+J28+J35+J42+J49+J56+J63+J70+J77+J84 -> 0 | K13: =K21+K28+K35+K42+K49+K56+K63+K70+K77+K84 -> 0 | L13: =L21+L28+L35+L42+L49+L56+L63+L70+L77+L84 -> 0 | M13: =M21+M28+M35+M42+M49+M56+M63+M70+M77+M84 -> 0 | ... W13: =W21+W28+W35+W42+W49+W56+W63+W70+W77+W84 -> #VALUE!
B14: f | C14: Lost and Found | F14: =F22+F29+F36+F43+F50+F57+F64+F71+F78+F85 -> 0 | G14: =G22+G29+G36+G43+G50+G57+G64+G71+G78+G85 -> 0 | H14: =H22+H29+H36+H43+H50+H57+H64+H71+H78+H85 -> 0 | I14: =I22+I29+I36+I43+I50+I57+I64+I71+I78+I85 -> 0 | J14: =J22+J29+J36+J43+J50+J57+J64+J71+J78+J85 -> 0 | K14: =K22+K29+K36+K43+K50+K57+K64+K71+K78+K85 -> 0 | L14: =L22+L29+L36+L43+L50+L57+L64+L71+L78+L85 -> 0 | M14: =M22+M29+M36+M43+M50+M57+M64+M71+M78+M85 -> 0 | ... W14: =W22+W29+W36+W43+W50+W57+W64+W71+W78+W85 -> #VALUE!
B15: g | C15: Priority Service | F15: =F23+F30+F37+F44+F51+F58+F65+F72+F79+F86 -> 0 | G15: =G23+G30+G37+G44+G51+G58+G65+G72+G79+G86 -> 0 | H15: =H23+H30+H37+H44+H51+H58+H65+H72+H79+H86 -> 0 | I15: =I23+I30+I37+I44+I51+I58+I65+I72+I79+I86 -> 0 | J15: =J23+J30+J37+J44+J51+J58+J65+J72+J79+J86 -> 0 | K15: =K23+K30+K37+K44+K51+K58+K65+K72+K79+K86 -> 0 | L15: =L23+L30+L37+L44+L51+L58+L65+L72+L79+L86 -> 0 | M15: =M23+M30+M37+M44+M51+M58+M65+M72+M79+M86 -> 0 | ... W15: =W23+W30+W37+W44+W51+W58+W65+W72+W79+W86 -> #VALUE!
A16: 4 | B16: Interaksi per channel
B17: a | C17: Telepon | D17: Pengaduan/Keluhan | F17: 0 | G17: 0 | H17: 0 | I17: 0 | J17: 0 | K17: 0 | L17: 0 | M17: 0 | N17: 0 | O17: 0 | P17: 0 | Q17: 0 | R17: 0 | S17: 0 | T17: 0 | U17: 0 | V17: 0
D18: Permintaan/Reservasi/Product Inquiry | F18: 0 | G18: 0 | H18: 0 | I18: 0 | J18: 0 | K18: 0 | L18: 0 | M18: 0 | N18: 0 | O18: 0 | P18: 0 | Q18: 0 | R18: 0 | S18: 0 | T18: 0 | U18: 0 | V18: 0
D19: Pertanyaan | F19: 0 | G19: 0 | H19: 0 | I19: 0 | J19: 0 | K19: 0 | L19: 0 | M19: 0 | N19: 0 | O19: 0 | P19: 0 | Q19: 0 | R19: 0 | S19: 0 | T19: 0 | U19: 0 | V19: 0
D20: Informasi | F20: 0 | G20: 0 | H20: 0 | I20: 0 | J20: 0 | K20: 0 | L20: 0 | M20: 0 | N20: 0 | O20: 0 | P20: 0 | Q20: 0 | R20: 0 | S20: 0 | T20: 0 | U20: 0 | V20: 0
D21: Apresiasi | F21: 0 | G21: 0 | H21: 0 | I21: 0 | J21: 0 | K21: 0 | L21: 0 | M21: 0 | N21: 0 | O21: 0 | P21: 0 | Q21: 0 | R21: 0 | S21: 0 | T21: 0 | U21: 0 | V21: 0
D22: Lost and Found | F22: 0 | G22: 0 | H22: 0 | I22: 0 | J22: 0 | K22: 0 | L22: 0 | M22: 0 | N22: 0 | O22: 0 | P22: 0 | Q22: 0 | R22: 0 | S22: 0 | T22: 0 | U22: 0 | V22: 0
D23: Priority Service | F23: 0 | G23: 0 | H23: 0 | I23: 0 | J23: 0 | K23: 0 | L23: 0 | M23: 0 | N23: 0 | O23: 0 | P23: 0 | Q23: 0 | R23: 0 | S23: 0 | T23: 0 | U23: 0 | V23: 0
B24: b | C24: Customer Sevice/tatap muka | D24: Pengaduan/Keluhan | F24: 0 | G24: 0 | H24: 0 | I24: 0 | J24: 0 | K24: 0 | L24: 0 | M24: 0 | N24: 0 | O24: 0 | P24: 0 | Q24: 0 | R24: 0 | S24: 0 | T24: 0 | U24: 0 | V24: 0
D25: Permintaan/Reservasi/Product Inquiry | F25: 0 | G25: 0 | H25: 0 | I25: 0 | J25: 0 | K25: 0 | L25: 0 | M25: 0 | N25: 0 | O25: 0 | P25: 0 | Q25: 0 | R25: 0 | S25: 0 | T25: 0 | U25: 0 | V25: 0
D26: Pertanyaan | F26: 0 | G26: 0 | H26: 0 | I26: 0 | J26: 0 | K26: 0 | L26: 0 | M26: 0 | N26: 0 | O26: 0 | P26: 0 | Q26: 0 | R26: 0 | S26: 0 | T26: 0 | U26: 0 | V26: 0
D27: Informasi | F27: 0 | G27: 0 | H27: 0 | I27: 0 | J27: 0 | K27: 0 | L27: 0 | M27: 0 | N27: 0 | O27: 0 | P27: 0 | Q27: 0 | R27: 0 | S27: 0 | T27: 0 | U27: 0 | V27: 0
D28: Apresiasi | F28: 0 | G28: 0 | H28: 0 | I28: 0 | J28: 0 | K28: 0 | L28: 0 | M28: 0 | N28: 0 | O28: 0 | P28: 0 | Q28: 0 | R28: 0 | S28: 0 | T28: 0 | U28: 0 | V28: 0
D29: Lost and Found | F29: 0 | G29: 0 | H29: 0 | I29: 0 | J29: 0 | K29: 0 | L29: 0 | M29: 0 | N29: 0 | O29: 0 | P29: 0 | Q29: 0 | R29: 0 | S29: 0 | T29: 0 | U29: 0 | V29: 0
D30: Priority Service | F30: 0 | G30: 0 | H30: 0 | I30: 0 | J30: 0 | K30: 0 | L30: 0 | M30: 0 | N30: 0 | O30: 0 | P30: 0 | Q30: 0 | R30: 0 | S30: 0 | T30: 0 | U30: 0 | V30: 0
B31: c | C31: Email | D31: Pengaduan/Keluhan | F31: 0 | G31: 0 | H31: 0 | I31: 0 | J31: 0 | K31: 0 | L31: 0 | M31: 0 | N31: 0 | O31: 0 | P31: 0 | Q31: 0 | R31: 0 | S31: 0 | T31: 0 | U31: 0 | V31: 0
D32: Permintaan/Reservasi/Product Inquiry | F32: 0 | G32: 0 | H32: 0 | I32: 0 | J32: 0 | K32: 0 | L32: 0 | M32: 0 | N32: 0 | O32: 0 | P32: 0 | Q32: 0 | R32: 0 | S32: 0 | T32: 0 | U32: 0 | V32: 0
D33: Pertanyaan | F33: 0 | G33: 0 | H33: 0 | I33: 0 | J33: 0 | K33: 0 | L33: 0 | M33: 0 | N33: 0 | O33: 0 | P33: 0 | Q33: 0 | R33: 0 | S33: 0 | T33: 0 | U33: 0 | V33: 0
D34: Informasi | F34: 0 | G34: 0 | H34: 0 | I34: 0 | J34: 0 | K34: 0 | L34: 0 | M34: 0 | N34: 0 | O34: 0 | P34: 0 | Q34: 0 | R34: 0 | S34: 0 | T34: 0 | U34: 0 | V34: 0
D35: Apresiasi | F35: 0 | G35: 0 | H35: 0 | I35: 0 | J35: 0 | K35: 0 | L35: 0 | M35: 0 | N35: 0 | O35: 0 | P35: 0 | Q35: 0 | R35: 0 | S35: 0 | T35: 0 | U35: 0 | V35: 0
D36: Lost and Found | F36: 0 | G36: 0 | H36: 0 | I36: 0 | J36: 0 | K36: 0 | L36: 0 | M36: 0 | N36: 0 | O36: 0 | P36: 0 | Q36: 0 | R36: 0 | S36: 0 | T36: 0 | U36: 0 | V36: 0
D37: Priority Service | F37: 0 | G37: 0 | H37: 0 | I37: 0 | J37: 0 | K37: 0 | L37: 0 | M37: 0 | N37: 0 | O37: 0 | P37: 0 | Q37: 0 | R37: 0 | S37: 0 | T37: 0 | U37: 0 | V37: 0
B38: d | C38: Kotak Saran | D38: Pengaduan/Keluhan | F38: 0 | G38: 0 | H38: 0 | I38: 0 | J38: 0 | K38: 0 | L38: 0 | M38: 0 | N38: 0 | O38: 0 | P38: 0 | Q38: 0 | R38: 0 | S38: 0 | T38: 0 | U38: 0 | V38: 0
D39: Permintaan/Reservasi/Product Inquiry | F39: 0 | G39: 0 | H39: 0 | I39: 0 | J39: 0 | K39: 0 | L39: 0 | M39: 0 | N39: 0 | O39: 0 | P39: 0 | Q39: 0 | R39: 0 | S39: 0 | T39: 0 | U39: 0 | V39: 0
D40: Pertanyaan | F40: 0 | G40: 0 | H40: 0 | I40: 0 | J40: 0 | K40: 0 | L40: 0 | M40: 0 | N40: 0 | O40: 0 | P40: 0 | Q40: 0 | R40: 0 | S40: 0 | T40: 0 | U40: 0 | V40: 0
...

Sheet Data
A1: No | B1: Item Data | E1: Keterangan Pengisian | F1: 45658 | G1: 45689 | H1: 45717 | I1: 45748 | J1: Mei 2025 | K1: Juni 2025 | L1: Juli 2025 | M1: Ags 2025 | N1: 45901 | O1: Okt 2025 | P1: 45962 | Q1: Des 2025 | R1: 46023 | S1: 46054 | T1: 46082 | U1: 46113 | V1: Mei 2026 | W1: Juni 2026 | X1: Juli 2026
A2: 1 | B2: Jumlah Pengunjung | E2: Data Total Pengunjung (Per Cabang / Line of Business) | F2: 453639 | G2: 281302 | H2: 68929 | I2: 387606 | J2: 336253 | K2: 369979 | L2: 412770 | M2: 250523 | N2: 229843 | O2: 241379 | P2: 244007 | Q2: 474408 | R2: 322284 | S2: 168909 | T2: 262443 | U2: 256150 | V2: 383909 | W2: 413329
A3: 2 | B3: Total Interaksi | E3: Total Interaksi (Per Cabang / Line of Business) | F3: 76 | G3: 930 | H3: 512 | I3: 1759 | J3: 1663 | K3: 1222 | L3: 1438 | M3: 112 | N3: 273 | O3: 1081 | P3: 1232 | Q3: 1149 | R3: 1920 | S3: 1377 | T3: 1769 | U3: 1751 | V3: 2093 | W3: 2557
A4: 3 | B4: Jumlah interaksi per-kategory | E4: Total interaksi per kategori (kategori disesuaikan dengan yang ada di member)(Per Cabang / Line of Business)
C5: Permintaan Informasi (contoh)
C6: Request (Contoh)
C7: Keluhan (Contoh)
A8: 4 | B8: Interaksi per channel | E8: Total Interaksi per channel (channel disesuaikan dengan yang ada di member)(Per Cabang / Line of Business) | F8: 45658 | G8: 45689 | H8: 45717 | I8: 45748 | J8: Mei 2025 | K8: Juni 2025 | L8: Juli 2025 | M8: Ags 2025 | N8: 45901 | O8: Okt 2025 | P8: 45962 | Q8: Des 2025 | R8: 46023 | S8: 46054 | T8: 46082 | U8: 46113 | V8: Mei 2026 | W8: Juni 2026 | X8: Juli 2026
C9: Voice (Incoming Call) | D9: Informasi | F9: 43 | G9: 31 | H9: 11 | I9: 77 | J9: 65 | K9: 106 | L9: 133 | M9: 49 | N9: 8 | O9: 61 | P9: 94 | Q9: 67 | R9: 142 | S9: 104 | T9: 139 | U9: 113 | V9: 124 | W9: 81
D10: Pengaduan/Keluhan | F10: 0 | G10: 0 | H10: 0 | I10: 3 | J10: 0 | K10: 0 | L10: 3 | M10: 1 | N10: 1 | O10: 6 | P10: 0 | Q10: 0 | R10: 0 | S10: 0 | T10: 0 | U10: 0 | V10: 1 | W10: 3
D11: Permohonan | F11: 0 | G11: 0 | H11: 0 | I11: 0 | J11: 0 | K11: 0 | L11: 0 | M11: 1 | N11: 0 | O11: 1 | P11: 1 | Q11: 0 | R11: 6 | S11: 1 | T11: 1 | U11: 2 | V11: 4 | W11: 5
D12: Lost & Found | R12: 1 | S12: 1 | T12: 1 | U12: 1 | V12: 0 | W12: 3
D13: Priority Service | R13: 3 | S13: 3 | T13: 4 | U13: 3 | V13: 0 | W13: 7
C14: Live Chat | D14: Informasi
D15: Keluhan
C16: Customer Service (WA Chat) | D16: Informasi | F16: 1456 | G16: 891 | H16: 497 | I16: 1666 | J16: 1588 | K16: 1102 | L16: 1280 | M16: 19 | N16: 255 | O16: 987 | P16: 1095 | Q16: 1069 | R16: 1706 | S16: 1222 | T16: 1553 | U16: 1565 | V16: 1893 | W16: 2344
D17: Pengaduan/Keluhan | F17: 15 | G17: 8 | H17: 4 | I17: 13 | J17: 10 | K17: 14 | L17: 22 | M17: 24 | N17: 5 | O17: 19 | P17: 17 | Q17: 7 | R17: 8 | S17: 2 | T17: 0 | U17: 3 | V17: 3 | W17: 11
D18: Permohonan | F18: 9 | G18: 0 | H18: 0 | I18: 0 | J18: 0 | K18: 0 | L18: 0 | M18: 18 | N18: 4 | O18: 7 | P18: 25 | Q18: 6 | R18: 30 | S18: 22 | T18: 16 | U18: 32 | V18: 34 | W18: 40
D19: Lost & Found | F19: 0 | G19: 0 | H19: 0 | I19: 0 | J19: 0 | K19: 0 | L19: 0 | M19: 0 | N19: 0 | O19: 0 | P19: 0 | Q19: 0 | R19: 16 | S19: 8 | T19: 14 | U19: 19 | V19: 17 | W19: 33
D20: Priority Service | F20: 0 | G20: 0 | H20: 0 | I20: 0 | J20: 0 | K20: 0 | L20: 0 | M20: 0 | N20: 0 | O20: 0 | P20: 0 | Q20: 0 | R20: 8 | S20: 14 | T20: 41 | U20: 14 | V20: 20 | W20: 30
C21: Lainnya (silahkan ditambahkan)
A22: 5 | B22: Jumlah Customer Resolution per SLA | E22: Kategorisasi SLA disesuaikan dengan SLA yang di terapkan di masing-masing member (Per Cabang / Line of Business)
C23: 1 hari
C24: 2 hari
C25: 3 hari
C26: Lainnya (silahkan ditambahkan)
A27: 6 | B27: Average Handling Time (Contact Center) | E27: Durasi rata-rata interaksi pelanggan & untuk daftar channel dapat di tambahkan sesuai dengan channel yang ada di member (Per Cabang / Line of Business) | F27: 45658 | G27: 45689 | H27: 45717 | I27: 45748 | J27: Mei 2025 | K27: Juni 2025 | L27: Juli 2025 | M27: Ags 2025 | N27: 45901 | O27: Okt 2025 | P27: 45962 | Q27: Des 2025 | R27: 46023 | S27: 46054 | T27: 46082 | U27: 46113 | V27: Mei 2026 | W27: Juni 2026 | X27: Juli 2026
C28: Voice (diisi jika ada) | F28: 0 | G28: 0 | H28: 0 | I28: 0 | J28: 0 | K28: 0 | L28: 0 | M28: 0 | N28: 0 | O28: 0 | P28: 0 | Q28: 0 | R28: 0.001400463 | S28: 0.0045486111 | T28: 0.00063657407 | U28: 0.0084259259 | V28: 0.0028819444 | W28: 0.010416667
C29: WA Chat (diisi jika ada) | F29: 0 | G29: 0 | H29: 0 | I29: 0 | J29: 0 | K29: 0 | L29: 0 | M29: 0 | N29: 0 | O29: 0 | P29: 0 | Q29: 0 | R29: 0.0012384259 | S29: 0.0011226852 | T29: 0.0010300926 | U29: 0.0015393519 | V29: 0.001412037 | W29: 0.0015162037
C30: Live Chat (diisi jika ada)
C31: Social Media (diisi jika ada)
C32: Lainnya (silahkan ditambahkan)
