Workbook

Sheet ITDC
A2: CUSTOMER EXPERIENCE PERFORMANCE DATA
A3: 2025 - 2026
A4: ITDC
A6: No | B6: Parameters | D6: Unit | E6: 2025 | R6: 2026
E7: JAN | F7: FEB | G7: MAR | H7: APR | I7: MAY | J7: JUN | K7: JUL | L7: AUG | M7: SEP | N7: OCT | O7: NOV | P7: DEC | Q7: TOTAL | R7: JAN | S7: FEB | T7: MAR | U7: APR | V7: MEI | W7: JUNI
A8: 1 | B8: Customer Satisfaction (Survey Sensum)
B9: a. | C9: CSAT - Overall | D9: Scale 1-5 | N9: 4.75 | O9: 3.67 | P9: 4.67 | Q9: =AVERAGE(N9:P9) -> 4.3633333 | R9: 1 | S9: 3 | T9: 4.5 | U9: 4.5 | V9: 4 | W9: 5
B10: b. | C10: CSAT - People | D10: Scale 1-5 | N10: 4.75 | O10: 4 | P10: 4.67 | Q10: =AVERAGE(N10:P10) -> 4.4733333 | R10: 1 | S10: 3 | T10: 5 | U10: 4.5 | V10: 5 | W10: 5
B11: c. | C11: CSAT - Process | D11: Scale 1-5 | N11: 4.75 | O11: 4.33 | P11: 4.33 | Q11: =AVERAGE(N11:P11) -> 4.47 | R11: 1 | S11: 3 | T11: 4.5 | U11: 4.5 | V11: 5 | W11: 5
B12: d. | C12: CSAT - Premises | D12: Scale 1-5 | N12: 4.75 | O12: 3.67 | P12: 4.33 | Q12: =AVERAGE(N12:P12) -> 4.25 | R12: 1 | S12: 3 | T12: 4.5 | U12: 4.5 | V12: 5 | W12: 5
A13: 2 | B13: Social Media Monitoring
B14: a. | C14: Volume of Interaction | D14: Numbers | E14: =2402+1552+613+596+50237 -> 55400 | F14: =7690+302+5009+230+35599 -> 48830 | G14: =3504+591+1403+613+56209 -> 62320 | H14: =758000+2398+687+1022+3437 -> 765544 | I14: =1800000+2603+571+3455+256 -> 1806885 | J14: =1200000+321+597+248+405 -> 1201571 | K14: =3200000+2637+410+2681+198 -> 3205926 | L14: =3000000+2535+616446+250 -> 3619231 | M14: =6800000+1734+87+2694+197 -> 6804712 | N14: =11000000+2450+935+11305+198 -> 11014888 | O14: =1700000+1502+124+486+329 -> 1702441 | P14: =2600000+1311+306+1737+204 -> 2603558 | Q14: =SUM(E14:P14) -> 32891306 | R14: =2500000+98372+4230+120194+316 -> 2723112 | S14: =2200000+94633+1432+41062+429 -> 2337556 | T14: =2200000+39684+3019+17328+1726 -> 2261757 | U14: =62792+21475+4677+17568+1639 -> 108151 | V14: =72818+55783+106423+15324+1283 -> 251631 | W14: =115993+21142+1425+5839+1555 -> 145954
B15: b. | C15: Net Sentiment Score | D15: Percentage (%) | E15: 0.0521 | F15: 0.0821 | G15: 0.0351 | H15: 0.1597 | I15: 0.1319 | J15: 0.1113 | K15: 0.0792 | L15: 0.1016 | M15: 0.1678 | N15: 0.1726 | O15: 0.2 | P15: 0.2791 | Q15: 0.2593 | R15: =(69.53%+84.31%+23.59%)/3 -> 0.59143333 | S15: =(3.35%+58.57%+100%+6.31%)/4 -> 0.420575 | T15: =(13.03%+80.17%+21.86%)/3 -> 0.38353333 | U15: =(72.32%+43.37%+59.57%+34.15%+29.52%)/5 -> 0.47786 | V15: =(48.78%+47.19%+18.75%+16.67%+21.33%)/5 -> 0.30544 | W15: =(27.82%+29.44%+56%+81.82%+24.31%)/5 -> 0.43878
B16: c. | C16: Average Response Time | D16: Hours | E16: N/A | F16: N/A | G16: N/A | H16: N/A | I16: N/A | J16: N/A | K16: N/A | L16: N/A | M16: N/A | N16: N/A | O16: N/A | P16: N/A | Q16: N/A | R16: =(49.6+2.5)/2 -> 26.05 | S16: =(18.7+0.1+4.2)/3 -> 7.6666667 | T16: =(9.6+8)/2 -> 8.8 | U16: =(13.8+9.3+13.2+0.5)/4 -> 9.2 | V16: =(21.1+9.4+24.7+11.3)/4 -> 16.625 | W16: =(10.8+2.8+14)/3 -> 9.2
B17: d. | C17: Respons to Sentiment Ratio | D17: 0,00 - 1,00 | E17: 0.11 | F17: 0.03 | G17: 0.08 | H17: 0.03 | I17: 0.02 | J17: 0.01 | K17: 0.03 | L17: 0.02 | M17: 0.01 | N17: 0.01 | O17: 0.02 | P17: 0.05 | Q17: 0.02 | R17: =(0.001+0.11+0.04)/3 -> 0.050333333 | S17: =(0.03+0.1+1+0.1)/4 -> 0.3075 | T17: =(0.01+0.04+0.06)/3 -> 0.036666667 | U17: =(0.08+0.15+0.21+0.06+0.06)/5 -> 0.112 | V17: =(0.05+0.15+0.22+0.38+0.04)/5 -> 0.168 | W17: =(0.04+0.05+0.25+0.18)/4 -> 0.13
A18: 3 | B18: Complaint Handling
B19: a. | C19: Total | D19: Numbers | E19: 1 | F19: 7 | G19: 3 | H19: 4 | I19: 4 | J19: 2 | K19: 3 | L19: 1 | M19: 18 | N19: 10 | O19: 5 | P19: 6 | Q19: =SUM(E19:P19) -> 64 | R19: 14 | S19: 7 | T19: 3 | U19: 17 | V19: 13 | W19: 7
B20: b. | C20: Completed | D20: Numbers | E20: 1 | F20: 7 | G20: 3 | H20: 4 | I20: 4 | J20: 2 | K20: 3 | L20: 1 | M20: 18 | N20: 10 | O20: 5 | P20: 5 | Q20: =SUM(E20:P20) -> 63 | R20: 14 | S20: 7 | T20: 3 | U20: 17 | V20: 13 | W20: 6
B21: c. | C21: Progress | D21: Numbers | E21: 0 | F21: 0 | G21: 0 | H21: 0 | I21: 0 | J21: 0 | K21: 0 | L21: 0 | M21: 0 | N21: 0 | O21: 0 | P21: 1 | Q21: =SUM(E21:P21) -> 1 | R21: 0 | S21: 0 | T21: 0 | U21: 0 | V21: 0 | W21: 1
B22: d. | C22: Untouch | D22: Numbers | E22: 0 | F22: 0 | G22: 0 | H22: 0 | I22: 0 | J22: 0 | K22: 0 | L22: 0 | M22: 0 | N22: 0 | O22: 0 | P22: 0 | Q22: 0 | R22: 0 | S22: 0 | T22: 0 | U22: 0 | V22: 0 | W22: 0
B23: e. | C23: Complaint Resolution Rate | D23: Percentage (%) | E23: =E20/E19*100% -> 1 | F23: =F20/F19*100% -> 1 | G23: =G20/G19*100% -> 1 | H23: =H20/H19*100% -> 1 | I23: =I20/I19*100% -> 1 | J23: =J20/J19*100% -> 1 | K23: =K20/K19*100% -> 1 | L23: =L20/L19*100% -> 1 | ... P23: =P20/P19*100% -> 0.83333333 | Q23: =SUM(E23:P23)/12 -> 0.98611111 | R23: =R20/R19*100% -> 1 | S23: =S20/S19*100% -> 1 | T23: =T20/T19*100% -> 1 | U23: 1 | V23: 1 | W23: =W20/W19*100% -> 0.85714286
B24: f. | C24: Average Time Resolution | D24: Day | E24: N/A | F24: N/A | G24: N/A | H24: N/A | I24: N/A | J24: N/A | K24: N/A | L24: N/A | M24: N/A | N24: N/A | O24: N/A | P24: N/A | Q24: N/A | R24: N/A | S24: N/A | T24: N/A | U24: N/A | V24: N/A | W24: N/A
C25: *Data Januari - December 2025 hanya menggunakan data Themandalikagp
C26: *Tidak ada data Average Response Time dari akun Themandalikagp
C27: *Volume of Interaction adalah jumlah data dari 5 akun (Themandalikagp, ITDC, The Nusa Dua The Mandalika, dan The Golo Mori)
C28: *NSS, Average Response Time, dan RSR tahun 2026 pada bulan Januari - Juni adalah rata-rata data dari akun ITDC, The Nusa Dua, The Mandalika, The Golo Mori dan Themandalikagp, namun data pada bulan Januari - Maret juga merupakan data sample karena langitbiru baru GoLive di bulan April
C29: **NSS, Average Response Time, dan RSR pada bulan Januari, data hanya terdapat di akun ITDC, The Nusa Dua, dan Themandalikagp (gambar tertera di bawah)
C30: **NSS, Average Response Time, dan RSR pada bulan Februari, data hanya terdapat di akun ITDC, The Nusa Dua, The Golo Mori, dan Themandalikagp (gambar tertera di bawah)
C31: **NSS, Average Response Time, dan RSR pada bulan Maret, data hanya terdapat di akun ITDC, The Mandalika, dan Themandalikagp (gambar tertera di bawah)
C33: * Data Complain Handling diperoleh dari Data Pengaduan - Service Recovery INJ :
C34: https://injourneygroup-my.sharepoint.com/:x:/g/personal/cx_injourney_id/IQBWzSqU9QDrUNy2prbMgXzfAW-J4ysM73bBhVFq6kWq6pk

Sheet Data Statistik Total
A1: No | B1: Item Data | E1: Keterangan Pengisian | F1: 45658 | G1: 45689 | H1: 45717 | I1: 45748 | J1: 45778 | K1: 45809 | L1: 45839 | M1: 45870 | N1: 45901 | O1: 45931 | P1: 45962 | Q1: 45992 | R1: 46023 | S1: 46054 | T1: 46082 | U1: 46113 | V1: Mei-26 | W1: Jun-26
A2: 1 | B2: Jumlah Pengunjung | E2: Data Total Pengunjung (Per Cabang / Line of Business) | F2: ='statistik The Nusa Dua'!F2+'statistik The Mandalika'!F2+'statistik The Golo Mori'!F2+'statistik MGPA'!F2 -> 434656 | G2: ='statistik The Nusa Dua'!G2+'statistik The Mandalika'!G2+'statistik The Golo Mori'!G2+'statistik MGPA'!G2 -> 310216 | H2: ='statistik The Nusa Dua'!H2+'statistik The Mandalika'!H2+'statistik The Golo Mori'!H2+'statistik MGPA'!H2 -> 297466 | I2: ='statistik The Nusa Dua'!I2+'statistik The Mandalika'!I2+'statistik The Golo Mori'!I2+'statistik MGPA'!I2 -> 425195 | J2: ='statistik The Nusa Dua'!J2+'statistik The Mandalika'!J2+'statistik The Golo Mori'!J2+'statistik MGPA'!J2 -> 416265 | K2: ='statistik The Nusa Dua'!K2+'statistik The Mandalika'!K2+'statistik The Golo Mori'!K2+'statistik MGPA'!K2 -> 443401 | L2: ='statistik The Nusa Dua'!L2+'statistik The Mandalika'!L2+'statistik The Golo Mori'!L2+'statistik MGPA'!L2 -> 522720 | M2: ='statistik The Nusa Dua'!M2+'statistik The Mandalika'!M2+'statistik The Golo Mori'!M2+'statistik MGPA'!M2 -> 517774 | ... W2: ='statistik The Nusa Dua'!W2+'statistik The Mandalika'!W2+'statistik The Golo Mori'!W2+'statistik MGPA'!W2 -> 493397
A3: 2 | B3: Total Interaksi | E3: Total Interaksi (Per Cabang / Line of Business) dari Voice of Customer (pengaduan, permintaan, pertanyaan, informasi dan apresiasi). | F3: ='statistik The Nusa Dua'!F3+'statistik The Mandalika'!F3+'statistik The Golo Mori'!F3+'statistik MGPA'!F3+'statistik INU'!F3 -> 7 | G3: ='statistik The Nusa Dua'!G3+'statistik The Mandalika'!G3+'statistik The Golo Mori'!G3+'statistik MGPA'!G3+'statistik INU'!G3 -> 11 | H3: ='statistik The Nusa Dua'!H3+'statistik The Mandalika'!H3+'statistik The Golo Mori'!H3+'statistik MGPA'!H3+'statistik INU'!H3 -> 1 | I3: ='statistik The Nusa Dua'!I3+'statistik The Mandalika'!I3+'statistik The Golo Mori'!I3+'statistik MGPA'!I3+'statistik INU'!I3 -> 6 | J3: ='statistik The Nusa Dua'!J3+'statistik The Mandalika'!J3+'statistik The Golo Mori'!J3+'statistik MGPA'!J3+'statistik INU'!J3 -> 14 | K3: ='statistik The Nusa Dua'!K3+'statistik The Mandalika'!K3+'statistik The Golo Mori'!K3+'statistik MGPA'!K3+'statistik INU'!K3 -> 10 | L3: ='statistik The Nusa Dua'!L3+'statistik The Mandalika'!L3+'statistik The Golo Mori'!L3+'statistik MGPA'!L3+'statistik INU'!L3 -> 19 | M3: ='statistik The Nusa Dua'!M3+'statistik The Mandalika'!M3+'statistik The Golo Mori'!M3+'statistik MGPA'!M3+'statistik INU'!M3 -> 23 | ... W3: ='statistik The Nusa Dua'!W3+'statistik The Mandalika'!W3+'statistik The Golo Mori'!W3+'statistik MGPA'!W3+'statistik INU'!W3 -> 86
A4: 3 | B4: Jumlah interaksi per-kategory
B5: a | C5: Permintaan Informasi | E5: Bersumber dari Telepon, Customer Service/tatap muka, Email, Kotak Saran, Live Chat, Whatsapp, Instagram dan Twitter | F5: ='statistik The Nusa Dua'!F5+'statistik The Mandalika'!F5+'statistik The Golo Mori'!F5+'statistik MGPA'!F5+'statistik INU'!F5 -> 0 | G5: ='statistik The Nusa Dua'!G5+'statistik The Mandalika'!G5+'statistik The Golo Mori'!G5+'statistik MGPA'!G5+'statistik INU'!G5 -> 2 | H5: ='statistik The Nusa Dua'!H5+'statistik The Mandalika'!H5+'statistik The Golo Mori'!H5+'statistik MGPA'!H5+'statistik INU'!H5 -> 0 | I5: ='statistik The Nusa Dua'!I5+'statistik The Mandalika'!I5+'statistik The Golo Mori'!I5+'statistik MGPA'!I5+'statistik INU'!I5 -> 0 | J5: ='statistik The Nusa Dua'!J5+'statistik The Mandalika'!J5+'statistik The Golo Mori'!J5+'statistik MGPA'!J5+'statistik INU'!J5 -> 0 | K5: ='statistik The Nusa Dua'!K5+'statistik The Mandalika'!K5+'statistik The Golo Mori'!K5+'statistik MGPA'!K5+'statistik INU'!K5 -> 0 | L5: ='statistik The Nusa Dua'!L5+'statistik The Mandalika'!L5+'statistik The Golo Mori'!L5+'statistik MGPA'!L5+'statistik INU'!L5 -> 1 | M5: ='statistik The Nusa Dua'!M5+'statistik The Mandalika'!M5+'statistik The Golo Mori'!M5+'statistik MGPA'!M5+'statistik INU'!M5 -> 1 | ... W5: ='statistik The Nusa Dua'!W5+'statistik The Mandalika'!W5+'statistik The Golo Mori'!W5+'statistik MGPA'!W5+'statistik INU'!W5 -> 25
B6: b | C6: Request | F6: ='statistik The Nusa Dua'!F6+'statistik The Mandalika'!F6+'statistik The Golo Mori'!F6+'statistik MGPA'!F6+'statistik INU'!F6 -> 1 | G6: ='statistik The Nusa Dua'!G6+'statistik The Mandalika'!G6+'statistik The Golo Mori'!G6+'statistik MGPA'!G6+'statistik INU'!G6 -> 2 | H6: ='statistik The Nusa Dua'!H6+'statistik The Mandalika'!H6+'statistik The Golo Mori'!H6+'statistik MGPA'!H6+'statistik INU'!H6 -> 0 | I6: ='statistik The Nusa Dua'!I6+'statistik The Mandalika'!I6+'statistik The Golo Mori'!I6+'statistik MGPA'!I6+'statistik INU'!I6 -> 0 | J6: ='statistik The Nusa Dua'!J6+'statistik The Mandalika'!J6+'statistik The Golo Mori'!J6+'statistik MGPA'!J6+'statistik INU'!J6 -> 1 | K6: ='statistik The Nusa Dua'!K6+'statistik The Mandalika'!K6+'statistik The Golo Mori'!K6+'statistik MGPA'!K6+'statistik INU'!K6 -> 0 | L6: ='statistik The Nusa Dua'!L6+'statistik The Mandalika'!L6+'statistik The Golo Mori'!L6+'statistik MGPA'!L6+'statistik INU'!L6 -> 0 | M6: ='statistik The Nusa Dua'!M6+'statistik The Mandalika'!M6+'statistik The Golo Mori'!M6+'statistik MGPA'!M6+'statistik INU'!M6 -> 1 | ... W6: ='statistik The Nusa Dua'!W6+'statistik The Mandalika'!W6+'statistik The Golo Mori'!W6+'statistik MGPA'!W6+'statistik INU'!W6 -> 17
B7: c | C7: Keluhan | F7: ='statistik The Nusa Dua'!F7+'statistik The Mandalika'!F7+'statistik The Golo Mori'!F7+'statistik MGPA'!F7+'statistik INU'!F7 -> 5 | G7: ='statistik The Nusa Dua'!G7+'statistik The Mandalika'!G7+'statistik The Golo Mori'!G7+'statistik MGPA'!G7+'statistik INU'!G7 -> 5 | H7: ='statistik The Nusa Dua'!H7+'statistik The Mandalika'!H7+'statistik The Golo Mori'!H7+'statistik MGPA'!H7+'statistik INU'!H7 -> 1 | I7: ='statistik The Nusa Dua'!I7+'statistik The Mandalika'!I7+'statistik The Golo Mori'!I7+'statistik MGPA'!I7+'statistik INU'!I7 -> 6 | J7: ='statistik The Nusa Dua'!J7+'statistik The Mandalika'!J7+'statistik The Golo Mori'!J7+'statistik MGPA'!J7+'statistik INU'!J7 -> 8 | K7: ='statistik The Nusa Dua'!K7+'statistik The Mandalika'!K7+'statistik The Golo Mori'!K7+'statistik MGPA'!K7+'statistik INU'!K7 -> 6 | L7: ='statistik The Nusa Dua'!L7+'statistik The Mandalika'!L7+'statistik The Golo Mori'!L7+'statistik MGPA'!L7+'statistik INU'!L7 -> 10 | M7: ='statistik The Nusa Dua'!M7+'statistik The Mandalika'!M7+'statistik The Golo Mori'!M7+'statistik MGPA'!M7+'statistik INU'!M7 -> 14 | ... W7: ='statistik The Nusa Dua'!W7+'statistik The Mandalika'!W7+'statistik The Golo Mori'!W7+'statistik MGPA'!W7+'statistik INU'!W7 -> 18
B8: d | C8: ='statistik The Nusa Dua'!C8 -> Apresiasi | F8: ='statistik The Nusa Dua'!F8+'statistik The Mandalika'!F8+'statistik The Golo Mori'!F8+'statistik MGPA'!F8+'statistik INU'!F8 -> 1 | G8: ='statistik The Nusa Dua'!G8+'statistik The Mandalika'!G8+'statistik The Golo Mori'!G8+'statistik MGPA'!G8+'statistik INU'!G8 -> 2 | H8: ='statistik The Nusa Dua'!H8+'statistik The Mandalika'!H8+'statistik The Golo Mori'!H8+'statistik MGPA'!H8+'statistik INU'!H8 -> 0 | I8: ='statistik The Nusa Dua'!I8+'statistik The Mandalika'!I8+'statistik The Golo Mori'!I8+'statistik MGPA'!I8+'statistik INU'!I8 -> 0 | J8: ='statistik The Nusa Dua'!J8+'statistik The Mandalika'!J8+'statistik The Golo Mori'!J8+'statistik MGPA'!J8+'statistik INU'!J8 -> 5 | K8: ='statistik The Nusa Dua'!K8+'statistik The Mandalika'!K8+'statistik The Golo Mori'!K8+'statistik MGPA'!K8+'statistik INU'!K8 -> 4 | L8: ='statistik The Nusa Dua'!L8+'statistik The Mandalika'!L8+'statistik The Golo Mori'!L8+'statistik MGPA'!L8+'statistik INU'!L8 -> 8 | M8: ='statistik The Nusa Dua'!M8+'statistik The Mandalika'!M8+'statistik The Golo Mori'!M8+'statistik MGPA'!M8+'statistik INU'!M8 -> 7 | ... W8: ='statistik The Nusa Dua'!W8+'statistik The Mandalika'!W8+'statistik The Golo Mori'!W8+'statistik MGPA'!W8+'statistik INU'!W8 -> 26
A9: 4 | B9: Interaksi per channel
B10: a | C10: Telepon | D10: =C5 -> Permintaan Informasi | F10: ='statistik The Nusa Dua'!F10+'statistik The Mandalika'!F10+'statistik The Golo Mori'!F10+'statistik MGPA'!F10+'statistik INU'!F10 -> 0 | G10: ='statistik The Nusa Dua'!G10+'statistik The Mandalika'!G10+'statistik The Golo Mori'!G10+'statistik MGPA'!G10+'statistik INU'!G10 -> 0 | H10: ='statistik The Nusa Dua'!H10+'statistik The Mandalika'!H10+'statistik The Golo Mori'!H10+'statistik MGPA'!H10+'statistik INU'!H10 -> 0 | I10: ='statistik The Nusa Dua'!I10+'statistik The Mandalika'!I10+'statistik The Golo Mori'!I10+'statistik MGPA'!I10+'statistik INU'!I10 -> 0 | J10: ='statistik The Nusa Dua'!J10+'statistik The Mandalika'!J10+'statistik The Golo Mori'!J10+'statistik MGPA'!J10+'statistik INU'!J10 -> 0 | K10: ='statistik The Nusa Dua'!K10+'statistik The Mandalika'!K10+'statistik The Golo Mori'!K10+'statistik MGPA'!K10+'statistik INU'!K10 -> 0 | L10: ='statistik The Nusa Dua'!L10+'statistik The Mandalika'!L10+'statistik The Golo Mori'!L10+'statistik MGPA'!L10+'statistik INU'!L10 -> 0 | M10: ='statistik The Nusa Dua'!M10+'statistik The Mandalika'!M10+'statistik The Golo Mori'!M10+'statistik MGPA'!M10+'statistik INU'!M10 -> 0 | ... W10: ='statistik The Nusa Dua'!W10+'statistik The Mandalika'!W10+'statistik The Golo Mori'!W10+'statistik MGPA'!W10+'statistik INU'!W10 -> 3
D11: =C6 -> Request | F11: ='statistik The Nusa Dua'!F11+'statistik The Mandalika'!F11+'statistik The Golo Mori'!F11+'statistik MGPA'!F11+'statistik INU'!F11 -> 0 | G11: ='statistik The Nusa Dua'!G11+'statistik The Mandalika'!G11+'statistik The Golo Mori'!G11+'statistik MGPA'!G11+'statistik INU'!G11 -> 0 | H11: ='statistik The Nusa Dua'!H11+'statistik The Mandalika'!H11+'statistik The Golo Mori'!H11+'statistik MGPA'!H11+'statistik INU'!H11 -> 0 | I11: ='statistik The Nusa Dua'!I11+'statistik The Mandalika'!I11+'statistik The Golo Mori'!I11+'statistik MGPA'!I11+'statistik INU'!I11 -> 0 | J11: ='statistik The Nusa Dua'!J11+'statistik The Mandalika'!J11+'statistik The Golo Mori'!J11+'statistik MGPA'!J11+'statistik INU'!J11 -> 0 | K11: ='statistik The Nusa Dua'!K11+'statistik The Mandalika'!K11+'statistik The Golo Mori'!K11+'statistik MGPA'!K11+'statistik INU'!K11 -> 0 | L11: ='statistik The Nusa Dua'!L11+'statistik The Mandalika'!L11+'statistik The Golo Mori'!L11+'statistik MGPA'!L11+'statistik INU'!L11 -> 0 | M11: ='statistik The Nusa Dua'!M11+'statistik The Mandalika'!M11+'statistik The Golo Mori'!M11+'statistik MGPA'!M11+'statistik INU'!M11 -> 0 | ... W11: ='statistik The Nusa Dua'!W11+'statistik The Mandalika'!W11+'statistik The Golo Mori'!W11+'statistik MGPA'!W11+'statistik INU'!W11 -> 0
D12: =C7 -> Keluhan | F12: ='statistik The Nusa Dua'!F12+'statistik The Mandalika'!F12+'statistik The Golo Mori'!F12+'statistik MGPA'!F12+'statistik INU'!F12 -> 1 | G12: ='statistik The Nusa Dua'!G12+'statistik The Mandalika'!G12+'statistik The Golo Mori'!G12+'statistik MGPA'!G12+'statistik INU'!G12 -> 2 | H12: ='statistik The Nusa Dua'!H12+'statistik The Mandalika'!H12+'statistik The Golo Mori'!H12+'statistik MGPA'!H12+'statistik INU'!H12 -> 1 | I12: ='statistik The Nusa Dua'!I12+'statistik The Mandalika'!I12+'statistik The Golo Mori'!I12+'statistik MGPA'!I12+'statistik INU'!I12 -> 0 | J12: ='statistik The Nusa Dua'!J12+'statistik The Mandalika'!J12+'statistik The Golo Mori'!J12+'statistik MGPA'!J12+'statistik INU'!J12 -> 1 | K12: ='statistik The Nusa Dua'!K12+'statistik The Mandalika'!K12+'statistik The Golo Mori'!K12+'statistik MGPA'!K12+'statistik INU'!K12 -> 0 | L12: ='statistik The Nusa Dua'!L12+'statistik The Mandalika'!L12+'statistik The Golo Mori'!L12+'statistik MGPA'!L12+'statistik INU'!L12 -> 0 | M12: ='statistik The Nusa Dua'!M12+'statistik The Mandalika'!M12+'statistik The Golo Mori'!M12+'statistik MGPA'!M12+'statistik INU'!M12 -> 0 | ... W12: ='statistik The Nusa Dua'!W12+'statistik The Mandalika'!W12+'statistik The Golo Mori'!W12+'statistik MGPA'!W12+'statistik INU'!W12 -> 0
D13: =C8 -> Apresiasi | F13: ='statistik The Nusa Dua'!F13+'statistik The Mandalika'!F13+'statistik The Golo Mori'!F13+'statistik MGPA'!F13+'statistik INU'!F13 -> 0 | G13: ='statistik The Nusa Dua'!G13+'statistik The Mandalika'!G13+'statistik The Golo Mori'!G13+'statistik MGPA'!G13+'statistik INU'!G13 -> 0 | H13: ='statistik The Nusa Dua'!H13+'statistik The Mandalika'!H13+'statistik The Golo Mori'!H13+'statistik MGPA'!H13+'statistik INU'!H13 -> 0 | I13: ='statistik The Nusa Dua'!I13+'statistik The Mandalika'!I13+'statistik The Golo Mori'!I13+'statistik MGPA'!I13+'statistik INU'!I13 -> 0 | J13: ='statistik The Nusa Dua'!J13+'statistik The Mandalika'!J13+'statistik The Golo Mori'!J13+'statistik MGPA'!J13+'statistik INU'!J13 -> 0 | K13: ='statistik The Nusa Dua'!K13+'statistik The Mandalika'!K13+'statistik The Golo Mori'!K13+'statistik MGPA'!K13+'statistik INU'!K13 -> 0 | L13: ='statistik The Nusa Dua'!L13+'statistik The Mandalika'!L13+'statistik The Golo Mori'!L13+'statistik MGPA'!L13+'statistik INU'!L13 -> 0 | M13: ='statistik The Nusa Dua'!M13+'statistik The Mandalika'!M13+'statistik The Golo Mori'!M13+'statistik MGPA'!M13+'statistik INU'!M13 -> 0 | ... W13: ='statistik The Nusa Dua'!W13+'statistik The Mandalika'!W13+'statistik The Golo Mori'!W13+'statistik MGPA'!W13+'statistik INU'!W13 -> 0
B14: b | C14: Customer Sevice/tatap muka | D14: =C5 -> Permintaan Informasi | F14: ='statistik The Nusa Dua'!F14+'statistik The Mandalika'!F14+'statistik The Golo Mori'!F14+'statistik MGPA'!F14+'statistik INU'!F14 -> 0 | G14: ='statistik The Nusa Dua'!G14+'statistik The Mandalika'!G14+'statistik The Golo Mori'!G14+'statistik MGPA'!G14+'statistik INU'!G14 -> 0 | H14: ='statistik The Nusa Dua'!H14+'statistik The Mandalika'!H14+'statistik The Golo Mori'!H14+'statistik MGPA'!H14+'statistik INU'!H14 -> 0 | I14: ='statistik The Nusa Dua'!I14+'statistik The Mandalika'!I14+'statistik The Golo Mori'!I14+'statistik MGPA'!I14+'statistik INU'!I14 -> 0 | J14: ='statistik The Nusa Dua'!J14+'statistik The Mandalika'!J14+'statistik The Golo Mori'!J14+'statistik MGPA'!J14+'statistik INU'!J14 -> 0 | K14: ='statistik The Nusa Dua'!K14+'statistik The Mandalika'!K14+'statistik The Golo Mori'!K14+'statistik MGPA'!K14+'statistik INU'!K14 -> 0 | L14: ='statistik The Nusa Dua'!L14+'statistik The Mandalika'!L14+'statistik The Golo Mori'!L14+'statistik MGPA'!L14+'statistik INU'!L14 -> 0 | M14: ='statistik The Nusa Dua'!M14+'statistik The Mandalika'!M14+'statistik The Golo Mori'!M14+'statistik MGPA'!M14+'statistik INU'!M14 -> 0 | ... W14: ='statistik The Nusa Dua'!W14+'statistik The Mandalika'!W14+'statistik The Golo Mori'!W14+'statistik MGPA'!W14+'statistik INU'!W14 -> 0
D15: Permintaan/Reservasi/Product Inquiry | F15: ='statistik The Nusa Dua'!F15+'statistik The Mandalika'!F15+'statistik The Golo Mori'!F15+'statistik MGPA'!F15+'statistik INU'!F15 -> 0 | G15: ='statistik The Nusa Dua'!G15+'statistik The Mandalika'!G15+'statistik The Golo Mori'!G15+'statistik MGPA'!G15+'statistik INU'!G15 -> 0 | H15: ='statistik The Nusa Dua'!H15+'statistik The Mandalika'!H15+'statistik The Golo Mori'!H15+'statistik MGPA'!H15+'statistik INU'!H15 -> 0 | I15: ='statistik The Nusa Dua'!I15+'statistik The Mandalika'!I15+'statistik The Golo Mori'!I15+'statistik MGPA'!I15+'statistik INU'!I15 -> 0 | J15: ='statistik The Nusa Dua'!J15+'statistik The Mandalika'!J15+'statistik The Golo Mori'!J15+'statistik MGPA'!J15+'statistik INU'!J15 -> 0 | K15: ='statistik The Nusa Dua'!K15+'statistik The Mandalika'!K15+'statistik The Golo Mori'!K15+'statistik MGPA'!K15+'statistik INU'!K15 -> 0 | L15: ='statistik The Nusa Dua'!L15+'statistik The Mandalika'!L15+'statistik The Golo Mori'!L15+'statistik MGPA'!L15+'statistik INU'!L15 -> 0 | M15: ='statistik The Nusa Dua'!M15+'statistik The Mandalika'!M15+'statistik The Golo Mori'!M15+'statistik MGPA'!M15+'statistik INU'!M15 -> 0 | ... W15: ='statistik The Nusa Dua'!W15+'statistik The Mandalika'!W15+'statistik The Golo Mori'!W15+'statistik MGPA'!W15+'statistik INU'!W15 -> 0
D16: =C7 -> Keluhan | F16: ='statistik The Nusa Dua'!F16+'statistik The Mandalika'!F16+'statistik The Golo Mori'!F16+'statistik MGPA'!F16+'statistik INU'!F16 -> 0 | G16: ='statistik The Nusa Dua'!G16+'statistik The Mandalika'!G16+'statistik The Golo Mori'!G16+'statistik MGPA'!G16+'statistik INU'!G16 -> 0 | H16: ='statistik The Nusa Dua'!H16+'statistik The Mandalika'!H16+'statistik The Golo Mori'!H16+'statistik MGPA'!H16+'statistik INU'!H16 -> 0 | I16: ='statistik The Nusa Dua'!I16+'statistik The Mandalika'!I16+'statistik The Golo Mori'!I16+'statistik MGPA'!I16+'statistik INU'!I16 -> 0 | J16: ='statistik The Nusa Dua'!J16+'statistik The Mandalika'!J16+'statistik The Golo Mori'!J16+'statistik MGPA'!J16+'statistik INU'!J16 -> 3 | K16: ='statistik The Nusa Dua'!K16+'statistik The Mandalika'!K16+'statistik The Golo Mori'!K16+'statistik MGPA'!K16+'statistik INU'!K16 -> 0 | L16: ='statistik The Nusa Dua'!L16+'statistik The Mandalika'!L16+'statistik The Golo Mori'!L16+'statistik MGPA'!L16+'statistik INU'!L16 -> 1 | M16: ='statistik The Nusa Dua'!M16+'statistik The Mandalika'!M16+'statistik The Golo Mori'!M16+'statistik MGPA'!M16+'statistik INU'!M16 -> 1 | ... W16: ='statistik The Nusa Dua'!W16+'statistik The Mandalika'!W16+'statistik The Golo Mori'!W16+'statistik MGPA'!W16+'statistik INU'!W16 -> 1
D17: =C8 -> Apresiasi | F17: ='statistik The Nusa Dua'!F17+'statistik The Mandalika'!F17+'statistik The Golo Mori'!F17+'statistik MGPA'!F17+'statistik INU'!F17 -> 0 | G17: ='statistik The Nusa Dua'!G17+'statistik The Mandalika'!G17+'statistik The Golo Mori'!G17+'statistik MGPA'!G17+'statistik INU'!G17 -> 0 | H17: ='statistik The Nusa Dua'!H17+'statistik The Mandalika'!H17+'statistik The Golo Mori'!H17+'statistik MGPA'!H17+'statistik INU'!H17 -> 0 | I17: ='statistik The Nusa Dua'!I17+'statistik The Mandalika'!I17+'statistik The Golo Mori'!I17+'statistik MGPA'!I17+'statistik INU'!I17 -> 0 | J17: ='statistik The Nusa Dua'!J17+'statistik The Mandalika'!J17+'statistik The Golo Mori'!J17+'statistik MGPA'!J17+'statistik INU'!J17 -> 0 | K17: ='statistik The Nusa Dua'!K17+'statistik The Mandalika'!K17+'statistik The Golo Mori'!K17+'statistik MGPA'!K17+'statistik INU'!K17 -> 0 | L17: ='statistik The Nusa Dua'!L17+'statistik The Mandalika'!L17+'statistik The Golo Mori'!L17+'statistik MGPA'!L17+'statistik INU'!L17 -> 0 | M17: ='statistik The Nusa Dua'!M17+'statistik The Mandalika'!M17+'statistik The Golo Mori'!M17+'statistik MGPA'!M17+'statistik INU'!M17 -> 0 | ... W17: ='statistik The Nusa Dua'!W17+'statistik The Mandalika'!W17+'statistik The Golo Mori'!W17+'statistik MGPA'!W17+'statistik INU'!W17 -> 0
B18: c | C18: Email | D18: =C5 -> Permintaan Informasi | F18: ='statistik The Nusa Dua'!F18+'statistik The Mandalika'!F18+'statistik The Golo Mori'!F18+'statistik MGPA'!F18+'statistik INU'!F18 -> 0 | G18: ='statistik The Nusa Dua'!G18+'statistik The Mandalika'!G18+'statistik The Golo Mori'!G18+'statistik MGPA'!G18+'statistik INU'!G18 -> 0 | H18: ='statistik The Nusa Dua'!H18+'statistik The Mandalika'!H18+'statistik The Golo Mori'!H18+'statistik MGPA'!H18+'statistik INU'!H18 -> 0 | I18: ='statistik The Nusa Dua'!I18+'statistik The Mandalika'!I18+'statistik The Golo Mori'!I18+'statistik MGPA'!I18+'statistik INU'!I18 -> 0 | J18: ='statistik The Nusa Dua'!J18+'statistik The Mandalika'!J18+'statistik The Golo Mori'!J18+'statistik MGPA'!J18+'statistik INU'!J18 -> 0 | K18: ='statistik The Nusa Dua'!K18+'statistik The Mandalika'!K18+'statistik The Golo Mori'!K18+'statistik MGPA'!K18+'statistik INU'!K18 -> 0 | L18: ='statistik The Nusa Dua'!L18+'statistik The Mandalika'!L18+'statistik The Golo Mori'!L18+'statistik MGPA'!L18+'statistik INU'!L18 -> 0 | M18: ='statistik The Nusa Dua'!M18+'statistik The Mandalika'!M18+'statistik The Golo Mori'!M18+'statistik MGPA'!M18+'statistik INU'!M18 -> 0 | ... W18: ='statistik The Nusa Dua'!W18+'statistik The Mandalika'!W18+'statistik The Golo Mori'!W18+'statistik MGPA'!W18+'statistik INU'!W18 -> 0
D19: =C6 -> Request | F19: ='statistik The Nusa Dua'!F19+'statistik The Mandalika'!F19+'statistik The Golo Mori'!F19+'statistik MGPA'!F19+'statistik INU'!F19 -> 0 | G19: ='statistik The Nusa Dua'!G19+'statistik The Mandalika'!G19+'statistik The Golo Mori'!G19+'statistik MGPA'!G19+'statistik INU'!G19 -> 0 | H19: ='statistik The Nusa Dua'!H19+'statistik The Mandalika'!H19+'statistik The Golo Mori'!H19+'statistik MGPA'!H19+'statistik INU'!H19 -> 0 | I19: ='statistik The Nusa Dua'!I19+'statistik The Mandalika'!I19+'statistik The Golo Mori'!I19+'statistik MGPA'!I19+'statistik INU'!I19 -> 0 | J19: ='statistik The Nusa Dua'!J19+'statistik The Mandalika'!J19+'statistik The Golo Mori'!J19+'statistik MGPA'!J19+'statistik INU'!J19 -> 0 | K19: ='statistik The Nusa Dua'!K19+'statistik The Mandalika'!K19+'statistik The Golo Mori'!K19+'statistik MGPA'!K19+'statistik INU'!K19 -> 0 | L19: ='statistik The Nusa Dua'!L19+'statistik The Mandalika'!L19+'statistik The Golo Mori'!L19+'statistik MGPA'!L19+'statistik INU'!L19 -> 0 | M19: ='statistik The Nusa Dua'!M19+'statistik The Mandalika'!M19+'statistik The Golo Mori'!M19+'statistik MGPA'!M19+'statistik INU'!M19 -> 0 | ... W19: ='statistik The Nusa Dua'!W19+'statistik The Mandalika'!W19+'statistik The Golo Mori'!W19+'statistik MGPA'!W19+'statistik INU'!W19 -> 1
D20: =C7 -> Keluhan | F20: ='statistik The Nusa Dua'!F20+'statistik The Mandalika'!F20+'statistik The Golo Mori'!F20+'statistik MGPA'!F20+'statistik INU'!F20 -> 1 | G20: ='statistik The Nusa Dua'!G20+'statistik The Mandalika'!G20+'statistik The Golo Mori'!G20+'statistik MGPA'!G20+'statistik INU'!G20 -> 1 | H20: ='statistik The Nusa Dua'!H20+'statistik The Mandalika'!H20+'statistik The Golo Mori'!H20+'statistik MGPA'!H20+'statistik INU'!H20 -> 0 | I20: ='statistik The Nusa Dua'!I20+'statistik The Mandalika'!I20+'statistik The Golo Mori'!I20+'statistik MGPA'!I20+'statistik INU'!I20 -> 2 | J20: ='statistik The Nusa Dua'!J20+'statistik The Mandalika'!J20+'statistik The Golo Mori'!J20+'statistik MGPA'!J20+'statistik INU'!J20 -> 2 | K20: ='statistik The Nusa Dua'!K20+'statistik The Mandalika'!K20+'statistik The Golo Mori'!K20+'statistik MGPA'!K20+'statistik INU'!K20 -> 0 | L20: ='statistik The Nusa Dua'!L20+'statistik The Mandalika'!L20+'statistik The Golo Mori'!L20+'statistik MGPA'!L20+'statistik INU'!L20 -> 0 | M20: ='statistik The Nusa Dua'!M20+'statistik The Mandalika'!M20+'statistik The Golo Mori'!M20+'statistik MGPA'!M20+'statistik INU'!M20 -> 3 | ... W20: ='statistik The Nusa Dua'!W20+'statistik The Mandalika'!W20+'statistik The Golo Mori'!W20+'statistik MGPA'!W20+'statistik INU'!W20 -> 0
D21: =C8 -> Apresiasi | F21: ='statistik The Nusa Dua'!F21+'statistik The Mandalika'!F21+'statistik The Golo Mori'!F21+'statistik MGPA'!F21+'statistik INU'!F21 -> 0 | G21: ='statistik The Nusa Dua'!G21+'statistik The Mandalika'!G21+'statistik The Golo Mori'!G21+'statistik MGPA'!G21+'statistik INU'!G21 -> 0 | H21: ='statistik The Nusa Dua'!H21+'statistik The Mandalika'!H21+'statistik The Golo Mori'!H21+'statistik MGPA'!H21+'statistik INU'!H21 -> 0 | I21: ='statistik The Nusa Dua'!I21+'statistik The Mandalika'!I21+'statistik The Golo Mori'!I21+'statistik MGPA'!I21+'statistik INU'!I21 -> 0 | J21: ='statistik The Nusa Dua'!J21+'statistik The Mandalika'!J21+'statistik The Golo Mori'!J21+'statistik MGPA'!J21+'statistik INU'!J21 -> 0 | K21: ='statistik The Nusa Dua'!K21+'statistik The Mandalika'!K21+'statistik The Golo Mori'!K21+'statistik MGPA'!K21+'statistik INU'!K21 -> 0 | L21: ='statistik The Nusa Dua'!L21+'statistik The Mandalika'!L21+'statistik The Golo Mori'!L21+'statistik MGPA'!L21+'statistik INU'!L21 -> 0 | M21: ='statistik The Nusa Dua'!M21+'statistik The Mandalika'!M21+'statistik The Golo Mori'!M21+'statistik MGPA'!M21+'statistik INU'!M21 -> 0 | ... W21: ='statistik The Nusa Dua'!W21+'statistik The Mandalika'!W21+'statistik The Golo Mori'!W21+'statistik MGPA'!W21+'statistik INU'!W21 -> 0
B22: d | C22: Kotak Saran | D22: =D10 -> Permintaan Informasi | F22: ='statistik The Nusa Dua'!F22+'statistik The Mandalika'!F22+'statistik The Golo Mori'!F22+'statistik MGPA'!F22+'statistik INU'!F22 -> 0 | G22: ='statistik The Nusa Dua'!G22+'statistik The Mandalika'!G22+'statistik The Golo Mori'!G22+'statistik MGPA'!G22+'statistik INU'!G22 -> 0 | H22: ='statistik The Nusa Dua'!H22+'statistik The Mandalika'!H22+'statistik The Golo Mori'!H22+'statistik MGPA'!H22+'statistik INU'!H22 -> 0 | I22: ='statistik The Nusa Dua'!I22+'statistik The Mandalika'!I22+'statistik The Golo Mori'!I22+'statistik MGPA'!I22+'statistik INU'!I22 -> 0 | J22: ='statistik The Nusa Dua'!J22+'statistik The Mandalika'!J22+'statistik The Golo Mori'!J22+'statistik MGPA'!J22+'statistik INU'!J22 -> 0 | K22: ='statistik The Nusa Dua'!K22+'statistik The Mandalika'!K22+'statistik The Golo Mori'!K22+'statistik MGPA'!K22+'statistik INU'!K22 -> 0 | L22: ='statistik The Nusa Dua'!L22+'statistik The Mandalika'!L22+'statistik The Golo Mori'!L22+'statistik MGPA'!L22+'statistik INU'!L22 -> 0 | M22: ='statistik The Nusa Dua'!M22+'statistik The Mandalika'!M22+'statistik The Golo Mori'!M22+'statistik MGPA'!M22+'statistik INU'!M22 -> 0 | ... W22: ='statistik The Nusa Dua'!W22+'statistik The Mandalika'!W22+'statistik The Golo Mori'!W22+'statistik MGPA'!W22+'statistik INU'!W22 -> 0
D23: =D11 -> Request | F23: ='statistik The Nusa Dua'!F23+'statistik The Mandalika'!F23+'statistik The Golo Mori'!F23+'statistik MGPA'!F23+'statistik INU'!F23 -> 0 | G23: ='statistik The Nusa Dua'!G23+'statistik The Mandalika'!G23+'statistik The Golo Mori'!G23+'statistik MGPA'!G23+'statistik INU'!G23 -> 0 | H23: ='statistik The Nusa Dua'!H23+'statistik The Mandalika'!H23+'statistik The Golo Mori'!H23+'statistik MGPA'!H23+'statistik INU'!H23 -> 0 | I23: ='statistik The Nusa Dua'!I23+'statistik The Mandalika'!I23+'statistik The Golo Mori'!I23+'statistik MGPA'!I23+'statistik INU'!I23 -> 0 | J23: ='statistik The Nusa Dua'!J23+'statistik The Mandalika'!J23+'statistik The Golo Mori'!J23+'statistik MGPA'!J23+'statistik INU'!J23 -> 0 | K23: ='statistik The Nusa Dua'!K23+'statistik The Mandalika'!K23+'statistik The Golo Mori'!K23+'statistik MGPA'!K23+'statistik INU'!K23 -> 0 | L23: ='statistik The Nusa Dua'!L23+'statistik The Mandalika'!L23+'statistik The Golo Mori'!L23+'statistik MGPA'!L23+'statistik INU'!L23 -> 0 | M23: ='statistik The Nusa Dua'!M23+'statistik The Mandalika'!M23+'statistik The Golo Mori'!M23+'statistik MGPA'!M23+'statistik INU'!M23 -> 0 | ... W23: ='statistik The Nusa Dua'!W23+'statistik The Mandalika'!W23+'statistik The Golo Mori'!W23+'statistik MGPA'!W23+'statistik INU'!W23 -> 0
D24: =D12 -> Keluhan | F24: ='statistik The Nusa Dua'!F24+'statistik The Mandalika'!F24+'statistik The Golo Mori'!F24+'statistik MGPA'!F24+'statistik INU'!F24 -> 0 | G24: ='statistik The Nusa Dua'!G24+'statistik The Mandalika'!G24+'statistik The Golo Mori'!G24+'statistik MGPA'!G24+'statistik INU'!G24 -> 0 | H24: ='statistik The Nusa Dua'!H24+'statistik The Mandalika'!H24+'statistik The Golo Mori'!H24+'statistik MGPA'!H24+'statistik INU'!H24 -> 0 | I24: ='statistik The Nusa Dua'!I24+'statistik The Mandalika'!I24+'statistik The Golo Mori'!I24+'statistik MGPA'!I24+'statistik INU'!I24 -> 0 | J24: ='statistik The Nusa Dua'!J24+'statistik The Mandalika'!J24+'statistik The Golo Mori'!J24+'statistik MGPA'!J24+'statistik INU'!J24 -> 0 | K24: ='statistik The Nusa Dua'!K24+'statistik The Mandalika'!K24+'statistik The Golo Mori'!K24+'statistik MGPA'!K24+'statistik INU'!K24 -> 0 | L24: ='statistik The Nusa Dua'!L24+'statistik The Mandalika'!L24+'statistik The Golo Mori'!L24+'statistik MGPA'!L24+'statistik INU'!L24 -> 0 | M24: ='statistik The Nusa Dua'!M24+'statistik The Mandalika'!M24+'statistik The Golo Mori'!M24+'statistik MGPA'!M24+'statistik INU'!M24 -> 0 | ... W24: ='statistik The Nusa Dua'!W24+'statistik The Mandalika'!W24+'statistik The Golo Mori'!W24+'statistik MGPA'!W24+'statistik INU'!W24 -> 0
D25: =D13 -> Apresiasi | F25: ='statistik The Nusa Dua'!F25+'statistik The Mandalika'!F25+'statistik The Golo Mori'!F25+'statistik MGPA'!F25+'statistik INU'!F25 -> 0 | G25: ='statistik The Nusa Dua'!G25+'statistik The Mandalika'!G25+'statistik The Golo Mori'!G25+'statistik MGPA'!G25+'statistik INU'!G25 -> 0 | H25: ='statistik The Nusa Dua'!H25+'statistik The Mandalika'!H25+'statistik The Golo Mori'!H25+'statistik MGPA'!H25+'statistik INU'!H25 -> 0 | I25: ='statistik The Nusa Dua'!I25+'statistik The Mandalika'!I25+'statistik The Golo Mori'!I25+'statistik MGPA'!I25+'statistik INU'!I25 -> 0 | J25: ='statistik The Nusa Dua'!J25+'statistik The Mandalika'!J25+'statistik The Golo Mori'!J25+'statistik MGPA'!J25+'statistik INU'!J25 -> 0 | K25: ='statistik The Nusa Dua'!K25+'statistik The Mandalika'!K25+'statistik The Golo Mori'!K25+'statistik MGPA'!K25+'statistik INU'!K25 -> 0 | L25: ='statistik The Nusa Dua'!L25+'statistik The Mandalika'!L25+'statistik The Golo Mori'!L25+'statistik MGPA'!L25+'statistik INU'!L25 -> 0 | M25: ='statistik The Nusa Dua'!M25+'statistik The Mandalika'!M25+'statistik The Golo Mori'!M25+'statistik MGPA'!M25+'statistik INU'!M25 -> 0 | ... W25: ='statistik The Nusa Dua'!W25+'statistik The Mandalika'!W25+'statistik The Golo Mori'!W25+'statistik MGPA'!W25+'statistik INU'!W25 -> 0
B26: e | C26: Live Chat | D26: =D10 -> Permintaan Informasi | F26: ='statistik The Nusa Dua'!F26+'statistik The Mandalika'!F26+'statistik The Golo Mori'!F26+'statistik MGPA'!F26+'statistik INU'!F26 -> 0 | G26: ='statistik The Nusa Dua'!G26+'statistik The Mandalika'!G26+'statistik The Golo Mori'!G26+'statistik MGPA'!G26+'statistik INU'!G26 -> 0 | H26: ='statistik The Nusa Dua'!H26+'statistik The Mandalika'!H26+'statistik The Golo Mori'!H26+'statistik MGPA'!H26+'statistik INU'!H26 -> 0 | I26: ='statistik The Nusa Dua'!I26+'statistik The Mandalika'!I26+'statistik The Golo Mori'!I26+'statistik MGPA'!I26+'statistik INU'!I26 -> 0 | J26: ='statistik The Nusa Dua'!J26+'statistik The Mandalika'!J26+'statistik The Golo Mori'!J26+'statistik MGPA'!J26+'statistik INU'!J26 -> 0 | K26: ='statistik The Nusa Dua'!K26+'statistik The Mandalika'!K26+'statistik The Golo Mori'!K26+'statistik MGPA'!K26+'statistik INU'!K26 -> 0 | L26: ='statistik The Nusa Dua'!L26+'statistik The Mandalika'!L26+'statistik The Golo Mori'!L26+'statistik MGPA'!L26+'statistik INU'!L26 -> 0 | M26: ='statistik The Nusa Dua'!M26+'statistik The Mandalika'!M26+'statistik The Golo Mori'!M26+'statistik MGPA'!M26+'statistik INU'!M26 -> 0 | ... W26: ='statistik The Nusa Dua'!W26+'statistik The Mandalika'!W26+'statistik The Golo Mori'!W26+'statistik MGPA'!W26+'statistik INU'!W26 -> 0
D27: =D11 -> Request | F27: ='statistik The Nusa Dua'!F27+'statistik The Mandalika'!F27+'statistik The Golo Mori'!F27+'statistik MGPA'!F27+'statistik INU'!F27 -> 0 | G27: ='statistik The Nusa Dua'!G27+'statistik The Mandalika'!G27+'statistik The Golo Mori'!G27+'statistik MGPA'!G27+'statistik INU'!G27 -> 0 | H27: ='statistik The Nusa Dua'!H27+'statistik The Mandalika'!H27+'statistik The Golo Mori'!H27+'statistik MGPA'!H27+'statistik INU'!H27 -> 0 | I27: ='statistik The Nusa Dua'!I27+'statistik The Mandalika'!I27+'statistik The Golo Mori'!I27+'statistik MGPA'!I27+'statistik INU'!I27 -> 0 | J27: ='statistik The Nusa Dua'!J27+'statistik The Mandalika'!J27+'statistik The Golo Mori'!J27+'statistik MGPA'!J27+'statistik INU'!J27 -> 0 | K27: ='statistik The Nusa Dua'!K27+'statistik The Mandalika'!K27+'statistik The Golo Mori'!K27+'statistik MGPA'!K27+'statistik INU'!K27 -> 0 | L27: ='statistik The Nusa Dua'!L27+'statistik The Mandalika'!L27+'statistik The Golo Mori'!L27+'statistik MGPA'!L27+'statistik INU'!L27 -> 0 | M27: ='statistik The Nusa Dua'!M27+'statistik The Mandalika'!M27+'statistik The Golo Mori'!M27+'statistik MGPA'!M27+'statistik INU'!M27 -> 0 | ... W27: ='statistik The Nusa Dua'!W27+'statistik The Mandalika'!W27+'statistik The Golo Mori'!W27+'statistik MGPA'!W27+'statistik INU'!W27 -> 0
D28: =D12 -> Keluhan | F28: ='statistik The Nusa Dua'!F28+'statistik The Mandalika'!F28+'statistik The Golo Mori'!F28+'statistik MGPA'!F28+'statistik INU'!F28 -> 0 | G28: ='statistik The Nusa Dua'!G28+'statistik The Mandalika'!G28+'statistik The Golo Mori'!G28+'statistik MGPA'!G28+'statistik INU'!G28 -> 0 | H28: ='statistik The Nusa Dua'!H28+'statistik The Mandalika'!H28+'statistik The Golo Mori'!H28+'statistik MGPA'!H28+'statistik INU'!H28 -> 0 | I28: ='statistik The Nusa Dua'!I28+'statistik The Mandalika'!I28+'statistik The Golo Mori'!I28+'statistik MGPA'!I28+'statistik INU'!I28 -> 0 | J28: ='statistik The Nusa Dua'!J28+'statistik The Mandalika'!J28+'statistik The Golo Mori'!J28+'statistik MGPA'!J28+'statistik INU'!J28 -> 0 | K28: ='statistik The Nusa Dua'!K28+'statistik The Mandalika'!K28+'statistik The Golo Mori'!K28+'statistik MGPA'!K28+'statistik INU'!K28 -> 0 | L28: ='statistik The Nusa Dua'!L28+'statistik The Mandalika'!L28+'statistik The Golo Mori'!L28+'statistik MGPA'!L28+'statistik INU'!L28 -> 0 | M28: ='statistik The Nusa Dua'!M28+'statistik The Mandalika'!M28+'statistik The Golo Mori'!M28+'statistik MGPA'!M28+'statistik INU'!M28 -> 0 | ... W28: ='statistik The Nusa Dua'!W28+'statistik The Mandalika'!W28+'statistik The Golo Mori'!W28+'statistik MGPA'!W28+'statistik INU'!W28 -> 0
D29: =D13 -> Apresiasi | F29: ='statistik The Nusa Dua'!F29+'statistik The Mandalika'!F29+'statistik The Golo Mori'!F29+'statistik MGPA'!F29+'statistik INU'!F29 -> 0 | G29: ='statistik The Nusa Dua'!G29+'statistik The Mandalika'!G29+'statistik The Golo Mori'!G29+'statistik MGPA'!G29+'statistik INU'!G29 -> 0 | H29: ='statistik The Nusa Dua'!H29+'statistik The Mandalika'!H29+'statistik The Golo Mori'!H29+'statistik MGPA'!H29+'statistik INU'!H29 -> 0 | I29: ='statistik The Nusa Dua'!I29+'statistik The Mandalika'!I29+'statistik The Golo Mori'!I29+'statistik MGPA'!I29+'statistik INU'!I29 -> 0 | J29: ='statistik The Nusa Dua'!J29+'statistik The Mandalika'!J29+'statistik The Golo Mori'!J29+'statistik MGPA'!J29+'statistik INU'!J29 -> 0 | K29: ='statistik The Nusa Dua'!K29+'statistik The Mandalika'!K29+'statistik The Golo Mori'!K29+'statistik MGPA'!K29+'statistik INU'!K29 -> 0 | L29: ='statistik The Nusa Dua'!L29+'statistik The Mandalika'!L29+'statistik The Golo Mori'!L29+'statistik MGPA'!L29+'statistik INU'!L29 -> 0 | M29: ='statistik The Nusa Dua'!M29+'statistik The Mandalika'!M29+'statistik The Golo Mori'!M29+'statistik MGPA'!M29+'statistik INU'!M29 -> 0 | ... W29: ='statistik The Nusa Dua'!W29+'statistik The Mandalika'!W29+'statistik The Golo Mori'!W29+'statistik MGPA'!W29+'statistik INU'!W29 -> 0
B30: f | C30: SP4N Lapor! | D30: =D26 -> Permintaan Informasi | F30: ='statistik The Nusa Dua'!F30+'statistik The Mandalika'!F30+'statistik The Golo Mori'!F30+'statistik MGPA'!F30+'statistik INU'!F30 -> 0 | G30: ='statistik The Nusa Dua'!G30+'statistik The Mandalika'!G30+'statistik The Golo Mori'!G30+'statistik MGPA'!G30+'statistik INU'!G30 -> 0 | H30: ='statistik The Nusa Dua'!H30+'statistik The Mandalika'!H30+'statistik The Golo Mori'!H30+'statistik MGPA'!H30+'statistik INU'!H30 -> 0 | I30: ='statistik The Nusa Dua'!I30+'statistik The Mandalika'!I30+'statistik The Golo Mori'!I30+'statistik MGPA'!I30+'statistik INU'!I30 -> 0 | J30: ='statistik The Nusa Dua'!J30+'statistik The Mandalika'!J30+'statistik The Golo Mori'!J30+'statistik MGPA'!J30+'statistik INU'!J30 -> 0 | K30: ='statistik The Nusa Dua'!K30+'statistik The Mandalika'!K30+'statistik The Golo Mori'!K30+'statistik MGPA'!K30+'statistik INU'!K30 -> 0 | L30: ='statistik The Nusa Dua'!L30+'statistik The Mandalika'!L30+'statistik The Golo Mori'!L30+'statistik MGPA'!L30+'statistik INU'!L30 -> 0 | M30: ='statistik The Nusa Dua'!M30+'statistik The Mandalika'!M30+'statistik The Golo Mori'!M30+'statistik MGPA'!M30+'statistik INU'!M30 -> 0 | ... W30: ='statistik The Nusa Dua'!W30+'statistik The Mandalika'!W30+'statistik The Golo Mori'!W30+'statistik MGPA'!W30+'statistik INU'!W30 -> 0
D31: =D27 -> Request | F31: ='statistik The Nusa Dua'!F31+'statistik The Mandalika'!F31+'statistik The Golo Mori'!F31+'statistik MGPA'!F31+'statistik INU'!F31 -> 0 | G31: ='statistik The Nusa Dua'!G31+'statistik The Mandalika'!G31+'statistik The Golo Mori'!G31+'statistik MGPA'!G31+'statistik INU'!G31 -> 0 | H31: ='statistik The Nusa Dua'!H31+'statistik The Mandalika'!H31+'statistik The Golo Mori'!H31+'statistik MGPA'!H31+'statistik INU'!H31 -> 0 | I31: ='statistik The Nusa Dua'!I31+'statistik The Mandalika'!I31+'statistik The Golo Mori'!I31+'statistik MGPA'!I31+'statistik INU'!I31 -> 0 | J31: ='statistik The Nusa Dua'!J31+'statistik The Mandalika'!J31+'statistik The Golo Mori'!J31+'statistik MGPA'!J31+'statistik INU'!J31 -> 0 | K31: ='statistik The Nusa Dua'!K31+'statistik The Mandalika'!K31+'statistik The Golo Mori'!K31+'statistik MGPA'!K31+'statistik INU'!K31 -> 0 | L31: ='statistik The Nusa Dua'!L31+'statistik The Mandalika'!L31+'statistik The Golo Mori'!L31+'statistik MGPA'!L31+'statistik INU'!L31 -> 0 | M31: ='statistik The Nusa Dua'!M31+'statistik The Mandalika'!M31+'statistik The Golo Mori'!M31+'statistik MGPA'!M31+'statistik INU'!M31 -> 0 | ... W31: ='statistik The Nusa Dua'!W31+'statistik The Mandalika'!W31+'statistik The Golo Mori'!W31+'statistik MGPA'!W31+'statistik INU'!W31 -> 0
D32: =D28 -> Keluhan | F32: ='statistik The Nusa Dua'!F32+'statistik The Mandalika'!F32+'statistik The Golo Mori'!F32+'statistik MGPA'!F32+'statistik INU'!F32 -> 0 | G32: ='statistik The Nusa Dua'!G32+'statistik The Mandalika'!G32+'statistik The Golo Mori'!G32+'statistik MGPA'!G32+'statistik INU'!G32 -> 0 | H32: ='statistik The Nusa Dua'!H32+'statistik The Mandalika'!H32+'statistik The Golo Mori'!H32+'statistik MGPA'!H32+'statistik INU'!H32 -> 0 | I32: ='statistik The Nusa Dua'!I32+'statistik The Mandalika'!I32+'statistik The Golo Mori'!I32+'statistik MGPA'!I32+'statistik INU'!I32 -> 0 | J32: ='statistik The Nusa Dua'!J32+'statistik The Mandalika'!J32+'statistik The Golo Mori'!J32+'statistik MGPA'!J32+'statistik INU'!J32 -> 0 | K32: ='statistik The Nusa Dua'!K32+'statistik The Mandalika'!K32+'statistik The Golo Mori'!K32+'statistik MGPA'!K32+'statistik INU'!K32 -> 0 | L32: ='statistik The Nusa Dua'!L32+'statistik The Mandalika'!L32+'statistik The Golo Mori'!L32+'statistik MGPA'!L32+'statistik INU'!L32 -> 0 | M32: ='statistik The Nusa Dua'!M32+'statistik The Mandalika'!M32+'statistik The Golo Mori'!M32+'statistik MGPA'!M32+'statistik INU'!M32 -> 0 | ... W32: ='statistik The Nusa Dua'!W32+'statistik The Mandalika'!W32+'statistik The Golo Mori'!W32+'statistik MGPA'!W32+'statistik INU'!W32 -> 0
D33: Apresiasi | F33: ='statistik The Nusa Dua'!F33+'statistik The Mandalika'!F33+'statistik The Golo Mori'!F33+'statistik MGPA'!F33+'statistik INU'!F33 -> 0 | G33: ='statistik The Nusa Dua'!G33+'statistik The Mandalika'!G33+'statistik The Golo Mori'!G33+'statistik MGPA'!G33+'statistik INU'!G33 -> 0 | H33: ='statistik The Nusa Dua'!H33+'statistik The Mandalika'!H33+'statistik The Golo Mori'!H33+'statistik MGPA'!H33+'statistik INU'!H33 -> 0 | I33: ='statistik The Nusa Dua'!I33+'statistik The Mandalika'!I33+'statistik The Golo Mori'!I33+'statistik MGPA'!I33+'statistik INU'!I33 -> 0 | J33: ='statistik The Nusa Dua'!J33+'statistik The Mandalika'!J33+'statistik The Golo Mori'!J33+'statistik MGPA'!J33+'statistik INU'!J33 -> 0 | K33: ='statistik The Nusa Dua'!K33+'statistik The Mandalika'!K33+'statistik The Golo Mori'!K33+'statistik MGPA'!K33+'statistik INU'!K33 -> 0 | L33: ='statistik The Nusa Dua'!L33+'statistik The Mandalika'!L33+'statistik The Golo Mori'!L33+'statistik MGPA'!L33+'statistik INU'!L33 -> 0 | M33: ='statistik The Nusa Dua'!M33+'statistik The Mandalika'!M33+'statistik The Golo Mori'!M33+'statistik MGPA'!M33+'statistik INU'!M33 -> 0 | ... W33: ='statistik The Nusa Dua'!W33+'statistik The Mandalika'!W33+'statistik The Golo Mori'!W33+'statistik MGPA'!W33+'statistik INU'!W33 -> 0
B34: g | C34: Whtasapp | D34: =D30 -> Permintaan Informasi | F34: ='statistik The Nusa Dua'!F34+'statistik The Mandalika'!F34+'statistik The Golo Mori'!F34+'statistik MGPA'!F34+'statistik INU'!F34 -> 0 | G34: ='statistik The Nusa Dua'!G34+'statistik The Mandalika'!G34+'statistik The Golo Mori'!G34+'statistik MGPA'!G34+'statistik INU'!G34 -> 0 | H34: ='statistik The Nusa Dua'!H34+'statistik The Mandalika'!H34+'statistik The Golo Mori'!H34+'statistik MGPA'!H34+'statistik INU'!H34 -> 0 | I34: ='statistik The Nusa Dua'!I34+'statistik The Mandalika'!I34+'statistik The Golo Mori'!I34+'statistik MGPA'!I34+'statistik INU'!I34 -> 0 | J34: ='statistik The Nusa Dua'!J34+'statistik The Mandalika'!J34+'statistik The Golo Mori'!J34+'statistik MGPA'!J34+'statistik INU'!J34 -> 0 | K34: ='statistik The Nusa Dua'!K34+'statistik The Mandalika'!K34+'statistik The Golo Mori'!K34+'statistik MGPA'!K34+'statistik INU'!K34 -> 0 | L34: ='statistik The Nusa Dua'!L34+'statistik The Mandalika'!L34+'statistik The Golo Mori'!L34+'statistik MGPA'!L34+'statistik INU'!L34 -> 0 | M34: ='statistik The Nusa Dua'!M34+'statistik The Mandalika'!M34+'statistik The Golo Mori'!M34+'statistik MGPA'!M34+'statistik INU'!M34 -> 0 | ... W34: ='statistik The Nusa Dua'!W34+'statistik The Mandalika'!W34+'statistik The Golo Mori'!W34+'statistik MGPA'!W34+'statistik INU'!W34 -> 15
D35: =D31 -> Request | F35: ='statistik The Nusa Dua'!F35+'statistik The Mandalika'!F35+'statistik The Golo Mori'!F35+'statistik MGPA'!F35+'statistik INU'!F35 -> 0 | G35: ='statistik The Nusa Dua'!G35+'statistik The Mandalika'!G35+'statistik The Golo Mori'!G35+'statistik MGPA'!G35+'statistik INU'!G35 -> 0 | H35: ='statistik The Nusa Dua'!H35+'statistik The Mandalika'!H35+'statistik The Golo Mori'!H35+'statistik MGPA'!H35+'statistik INU'!H35 -> 0 | I35: ='statistik The Nusa Dua'!I35+'statistik The Mandalika'!I35+'statistik The Golo Mori'!I35+'statistik MGPA'!I35+'statistik INU'!I35 -> 0 | J35: ='statistik The Nusa Dua'!J35+'statistik The Mandalika'!J35+'statistik The Golo Mori'!J35+'statistik MGPA'!J35+'statistik INU'!J35 -> 0 | K35: ='statistik The Nusa Dua'!K35+'statistik The Mandalika'!K35+'statistik The Golo Mori'!K35+'statistik MGPA'!K35+'statistik INU'!K35 -> 0 | L35: ='statistik The Nusa Dua'!L35+'statistik The Mandalika'!L35+'statistik The Golo Mori'!L35+'statistik MGPA'!L35+'statistik INU'!L35 -> 0 | M35: ='statistik The Nusa Dua'!M35+'statistik The Mandalika'!M35+'statistik The Golo Mori'!M35+'statistik MGPA'!M35+'statistik INU'!M35 -> 0 | ... W35: ='statistik The Nusa Dua'!W35+'statistik The Mandalika'!W35+'statistik The Golo Mori'!W35+'statistik MGPA'!W35+'statistik INU'!W35 -> 7
D36: =D32 -> Keluhan | F36: ='statistik The Nusa Dua'!F36+'statistik The Mandalika'!F36+'statistik The Golo Mori'!F36+'statistik MGPA'!F36+'statistik INU'!F36 -> 3 | G36: ='statistik The Nusa Dua'!G36+'statistik The Mandalika'!G36+'statistik The Golo Mori'!G36+'statistik MGPA'!G36+'statistik INU'!G36 -> 1 | H36: ='statistik The Nusa Dua'!H36+'statistik The Mandalika'!H36+'statistik The Golo Mori'!H36+'statistik MGPA'!H36+'statistik INU'!H36 -> 0 | I36: ='statistik The Nusa Dua'!I36+'statistik The Mandalika'!I36+'statistik The Golo Mori'!I36+'statistik MGPA'!I36+'statistik INU'!I36 -> 3 | J36: ='statistik The Nusa Dua'!J36+'statistik The Mandalika'!J36+'statistik The Golo Mori'!J36+'statistik MGPA'!J36+'statistik INU'!J36 -> 5 | K36: ='statistik The Nusa Dua'!K36+'statistik The Mandalika'!K36+'statistik The Golo Mori'!K36+'statistik MGPA'!K36+'statistik INU'!K36 -> 6 | L36: ='statistik The Nusa Dua'!L36+'statistik The Mandalika'!L36+'statistik The Golo Mori'!L36+'statistik MGPA'!L36+'statistik INU'!L36 -> 8 | M36: ='statistik The Nusa Dua'!M36+'statistik The Mandalika'!M36+'statistik The Golo Mori'!M36+'statistik MGPA'!M36+'statistik INU'!M36 -> 11 | ... W36: ='statistik The Nusa Dua'!W36+'statistik The Mandalika'!W36+'statistik The Golo Mori'!W36+'statistik MGPA'!W36+'statistik INU'!W36 -> 7
D37: =D33 -> Apresiasi | F37: ='statistik The Nusa Dua'!F37+'statistik The Mandalika'!F37+'statistik The Golo Mori'!F37+'statistik MGPA'!F37+'statistik INU'!F37 -> 0 | G37: ='statistik The Nusa Dua'!G37+'statistik The Mandalika'!G37+'statistik The Golo Mori'!G37+'statistik MGPA'!G37+'statistik INU'!G37 -> 0 | H37: ='statistik The Nusa Dua'!H37+'statistik The Mandalika'!H37+'statistik The Golo Mori'!H37+'statistik MGPA'!H37+'statistik INU'!H37 -> 0 | I37: ='statistik The Nusa Dua'!I37+'statistik The Mandalika'!I37+'statistik The Golo Mori'!I37+'statistik MGPA'!I37+'statistik INU'!I37 -> 0 | J37: ='statistik The Nusa Dua'!J37+'statistik The Mandalika'!J37+'statistik The Golo Mori'!J37+'statistik MGPA'!J37+'statistik INU'!J37 -> 4 | K37: ='statistik The Nusa Dua'!K37+'statistik The Mandalika'!K37+'statistik The Golo Mori'!K37+'statistik MGPA'!K37+'statistik INU'!K37 -> 4 | L37: ='statistik The Nusa Dua'!L37+'statistik The Mandalika'!L37+'statistik The Golo Mori'!L37+'statistik MGPA'!L37+'statistik INU'!L37 -> 8 | M37: ='statistik The Nusa Dua'!M37+'statistik The Mandalika'!M37+'statistik The Golo Mori'!M37+'statistik MGPA'!M37+'statistik INU'!M37 -> 6 | ... W37: ='statistik The Nusa Dua'!W37+'statistik The Mandalika'!W37+'statistik The Golo Mori'!W37+'statistik MGPA'!W37+'statistik INU'!W37 -> 9
B38: h | C38: Instagram | D38: =D34 -> Permintaan Informasi | F38: ='statistik The Nusa Dua'!F38+'statistik The Mandalika'!F38+'statistik The Golo Mori'!F38+'statistik MGPA'!F38+'statistik INU'!F38 -> 2 | G38: ='statistik The Nusa Dua'!G38+'statistik The Mandalika'!G38+'statistik The Golo Mori'!G38+'statistik MGPA'!G38+'statistik INU'!G38 -> 1 | H38: ='statistik The Nusa Dua'!H38+'statistik The Mandalika'!H38+'statistik The Golo Mori'!H38+'statistik MGPA'!H38+'statistik INU'!H38 -> 3 | I38: ='statistik The Nusa Dua'!I38+'statistik The Mandalika'!I38+'statistik The Golo Mori'!I38+'statistik MGPA'!I38+'statistik INU'!I38 -> 3 | J38: ='statistik The Nusa Dua'!J38+'statistik The Mandalika'!J38+'statistik The Golo Mori'!J38+'statistik MGPA'!J38+'statistik INU'!J38 -> 2 | K38: ='statistik The Nusa Dua'!K38+'statistik The Mandalika'!K38+'statistik The Golo Mori'!K38+'statistik MGPA'!K38+'statistik INU'!K38 -> 0 | L38: ='statistik The Nusa Dua'!L38+'statistik The Mandalika'!L38+'statistik The Golo Mori'!L38+'statistik MGPA'!L38+'statistik INU'!L38 -> 11 | M38: ='statistik The Nusa Dua'!M38+'statistik The Mandalika'!M38+'statistik The Golo Mori'!M38+'statistik MGPA'!M38+'statistik INU'!M38 -> 10 | ... W38: ='statistik The Nusa Dua'!W38+'statistik The Mandalika'!W38+'statistik The Golo Mori'!W38+'statistik MGPA'!W38+'statistik INU'!W38 -> 12
D39: =D35 -> Request | F39: ='statistik The Nusa Dua'!F39+'statistik The Mandalika'!F39+'statistik The Golo Mori'!F39+'statistik MGPA'!F39+'statistik INU'!F39 -> 0 | G39: ='statistik The Nusa Dua'!G39+'statistik The Mandalika'!G39+'statistik The Golo Mori'!G39+'statistik MGPA'!G39+'statistik INU'!G39 -> 0 | H39: ='statistik The Nusa Dua'!H39+'statistik The Mandalika'!H39+'statistik The Golo Mori'!H39+'statistik MGPA'!H39+'statistik INU'!H39 -> 0 | I39: ='statistik The Nusa Dua'!I39+'statistik The Mandalika'!I39+'statistik The Golo Mori'!I39+'statistik MGPA'!I39+'statistik INU'!I39 -> 0 | J39: ='statistik The Nusa Dua'!J39+'statistik The Mandalika'!J39+'statistik The Golo Mori'!J39+'statistik MGPA'!J39+'statistik INU'!J39 -> 0 | K39: ='statistik The Nusa Dua'!K39+'statistik The Mandalika'!K39+'statistik The Golo Mori'!K39+'statistik MGPA'!K39+'statistik INU'!K39 -> 0 | L39: ='statistik The Nusa Dua'!L39+'statistik The Mandalika'!L39+'statistik The Golo Mori'!L39+'statistik MGPA'!L39+'statistik INU'!L39 -> 0 | M39: ='statistik The Nusa Dua'!M39+'statistik The Mandalika'!M39+'statistik The Golo Mori'!M39+'statistik MGPA'!M39+'statistik INU'!M39 -> 0 | ... W39: ='statistik The Nusa Dua'!W39+'statistik The Mandalika'!W39+'statistik The Golo Mori'!W39+'statistik MGPA'!W39+'statistik INU'!W39 -> 9
D40: =D36 -> Keluhan | F40: ='statistik The Nusa Dua'!F40+'statistik The Mandalika'!F40+'statistik The Golo Mori'!F40+'statistik MGPA'!F40+'statistik INU'!F40 -> 0 | G40: ='statistik The Nusa Dua'!G40+'statistik The Mandalika'!G40+'statistik The Golo Mori'!G40+'statistik MGPA'!G40+'statistik INU'!G40 -> 1 | H40: ='statistik The Nusa Dua'!H40+'statistik The Mandalika'!H40+'statistik The Golo Mori'!H40+'statistik MGPA'!H40+'statistik INU'!H40 -> 0 | I40: ='statistik The Nusa Dua'!I40+'statistik The Mandalika'!I40+'statistik The Golo Mori'!I40+'statistik MGPA'!I40+'statistik INU'!I40 -> 1 | J40: ='statistik The Nusa Dua'!J40+'statistik The Mandalika'!J40+'statistik The Golo Mori'!J40+'statistik MGPA'!J40+'statistik INU'!J40 -> 0 | K40: ='statistik The Nusa Dua'!K40+'statistik The Mandalika'!K40+'statistik The Golo Mori'!K40+'statistik MGPA'!K40+'statistik INU'!K40 -> 0 | L40: ='statistik The Nusa Dua'!L40+'statistik The Mandalika'!L40+'statistik The Golo Mori'!L40+'statistik MGPA'!L40+'statistik INU'!L40 -> 0 | M40: ='statistik The Nusa Dua'!M40+'statistik The Mandalika'!M40+'statistik The Golo Mori'!M40+'statistik MGPA'!M40+'statistik INU'!M40 -> 0 | ... W40: ='statistik The Nusa Dua'!W40+'statistik The Mandalika'!W40+'statistik The Golo Mori'!W40+'statistik MGPA'!W40+'statistik INU'!W40 -> 9
...

Sheet Rekap
C5: 2025 | F5: 2026
C6: Oct | D6: Nov | E6: Dec | F6: Jan | G6: Feb | H6: Mar
B7: CSAT - Overall | C7: 4.75 | D7: 3.67 | E7: 4.67 | F7: 1 | G7: 3 | H7: 4.5
C9: 2025 | O9: 2026
C10: Jan | D10: Feb | E10: Mar | F10: Apr | G10: May | H10: Jun | I10: Jul | J10: Aug | K10: Sep | L10: Oct | M10: Nov | N10: Dec | O10: Jan | P10: Feb | Q10: Mar
B11: Volume of Interaction | C11: =2402+1552+613+596 -> 5163 | D11: =7690+302+5009+230 -> 13231 | E11: =3504+591+1403+613 -> 6111 | F11: =758000+2398+687+1022+3437 -> 765544 | G11: =1800000+2603+571+3455+256 -> 1806885 | H11: =1200000+321+597+248+405 -> 1201571 | I11: =3200000+2637+410+2681+198 -> 3205926 | J11: =3000000+2535+616446+250 -> 3619231 | K11: =6800000+1734+87+2694+197 -> 6804712 | L11: =11000000+2450+935+11305+198 -> 11014888 | M11: =1700000+1502+124+486+329 -> 1702441 | N11: =2600000+1311+306+1737+204 -> 2603558 | O11: =2500000+98372+4230+120194+316 -> 2723112 | P11: =2200000+94633+1432+41062+429 -> 2337556 | Q11: =2200000+39684+3019+17328+1726 -> 2261757
C14: 2025 | O14: 2026
C15: Jan | D15: Feb | E15: Mar | F15: Apr | G15: May | H15: Jun | I15: Jul | J15: Aug | K15: Sep | L15: Oct | M15: Nov | N15: Dec | O15: Jan | P15: Feb | Q15: Mar
B16: Total Complaint | C16: =ITDC!E19 -> 1 | D16: =ITDC!F19 -> 7 | E16: =ITDC!G19 -> 3 | F16: =ITDC!H19 -> 4 | G16: =ITDC!I19 -> 4 | H16: =ITDC!J19 -> 2 | I16: =ITDC!K19 -> 3 | J16: =ITDC!L19 -> 1 | ... N16: =ITDC!P19 -> 6 | O16: =ITDC!R19 -> 14 | P16: =ITDC!S19 -> 7 | Q16: =ITDC!T19 -> 3

Sheet Bisa dihapus
C5: 2025 | F5: 2026
C6: Oct | D6: Nov | E6: Dec | F6: Jan | G6: Feb | H6: Mar
B7: CSAT - Overall | C7: 4.75 | D7: 3.67 | E7: 4.67 | F7: 1 | G7: 3 | H7: 4.5
C9: 2025 | O9: 2026
C10: Jan | D10: Feb | E10: Mar | F10: Apr | G10: May | H10: Jun | I10: Jul | J10: Aug | K10: Sep | L10: Oct | M10: Nov | N10: Dec | O10: Jan | P10: Feb | Q10: Mar
B11: Volume of Interaction | C11: =2402+1552+613+596 -> 5163 | D11: =7690+302+5009+230 -> 13231 | E11: =3504+591+1403+613 -> 6111 | F11: =758000+2398+687+1022+3437 -> 765544 | G11: =1800000+2603+571+3455+256 -> 1806885 | H11: =1200000+321+597+248+405 -> 1201571 | I11: =3200000+2637+410+2681+198 -> 3205926 | J11: =3000000+2535+616446+250 -> 3619231 | K11: =6800000+1734+87+2694+197 -> 6804712 | L11: =11000000+2450+935+11305+198 -> 11014888 | M11: =1700000+1502+124+486+329 -> 1702441 | N11: =2600000+1311+306+1737+204 -> 2603558 | O11: =2500000+98372+4230+120194+316 -> 2723112 | P11: =2200000+94633+1432+41062+429 -> 2337556 | Q11: =2200000+39684+3019+17328+1726 -> 2261757
C14: 2025 | O14: 2026
C15: Jan | D15: Feb | E15: Mar | F15: Apr | G15: May | H15: Jun | I15: Jul | J15: Aug | K15: Sep | L15: Oct | M15: Nov | N15: Dec | O15: Jan | P15: Feb | Q15: Mar
B16: Total Complaint | C16: 80 | D16: 95 | E16: 110 | F16: 120 | G16: 185 | H16: 160 | I16: 245 | J16: 275 | K16: 230 | L16: 210 | M16: 195 | N16: 180 | O16: 190 | P16: 205 | Q16: 220

Sheet statistik The Nusa Dua
B1: Item Data | E1: Keterangan Pengisian | F1: 45658 | G1: 45689 | H1: 45717 | I1: 45748 | J1: 45778 | K1: 45809 | L1: 45839 | M1: 45870 | N1: 45901 | O1: 45931 | P1: 45962 | Q1: 45992 | R1: 46023 | S1: 46054 | T1: 46082 | U1: 46113 | V1: Mei 2026 | W1: Juni 2026
A2: 1 | B2: Jumlah Pengunjung | E2: Data Total Pengunjung (Per Cabang / Line of Business) | F2: 312247 | G2: 229229 | H2: 228079 | I2: 287663 | J2: 291710 | K2: 313307 | L2: 369481 | M2: 361151 | N2: 353482 | O2: 361554 | P2: 320856 | Q2: 366898 | R2: 330223 | S2: 258846 | T2: 274467 | U2: 293318 | V2: 303023 | W2: 323035 | X2: noted: data sementara. untuk data kunjungan bulan Juni akan kami pada tanggal 10 Juni
A3: 2 | B3: Total Interaksi | E3: Total Interaksi (Per Cabang / Line of Business) | F3: =SUM(F5:F8) -> 3 | G3: =SUM(G5:G8) -> 4 | H3: =SUM(H5:H8) -> 1 | I3: =SUM(I5:I8) -> 4 | J3: =SUM(J5:J8) -> 4 | K3: =SUM(K5:K8) -> 2 | L3: =SUM(L5:L8) -> 1 | M3: =SUM(M5:M8) -> 7 | ... W3: =SUM(W5:W8) -> 15
A4: 3 | B4: Jumlah interaksi per-kategory | E4: Total interaksi per kategori (kategori disesuaikan dengan yang ada di member)(Per Cabang / Line of Business)
